Workbook

Sheet Dashboard
A1: Play Before Pixels: financial model dashboard
A2: AlphaPlay LLC (Maryland) d/b/a Play Before Pixels. Revised draft for the founder, September 28, 2026. Planning estimates only: these are not forecasts of income or promises of results. Base plan: lean-path costs, first sales Dec 2026, and the school wave, board book and retail all off. Budget on Conservative; measure progress against Expected. Change any blue cell on Assumptions and every tab updates.
A5: Measure | B5: Conservative | C5: Expected | D5: Strong | E5: Where it comes from
A6: Sales and profit by year (model year 1 = Oct 2026 - Sep 2027)
A7: Gross sales, year 1 | B7: ='36-Month Forecast'!AM120 | C7: ='36-Month Forecast'!AM254 | D7: ='36-Month Forecast'!AM388 | E7: 36-Month Forecast
A8: Gross sales, year 2 | B8: ='36-Month Forecast'!AN120 | C8: ='36-Month Forecast'!AN254 | D8: ='36-Month Forecast'!AN388
A9: Gross sales, year 3 | B9: ='36-Month Forecast'!AO120 | C9: ='36-Month Forecast'!AO254 | D9: ='36-Month Forecast'!AO388
A10: Net contribution, year 1 | B10: ='36-Month Forecast'!AM121 | C10: ='36-Month Forecast'!AM255 | D10: ='36-Month Forecast'!AM389 | E10: After platform, payment, print/POD and fulfilment costs
A11: Net contribution, year 2 | B11: ='36-Month Forecast'!AN121 | C11: ='36-Month Forecast'!AN255 | D11: ='36-Month Forecast'!AN389
A12: Net contribution, year 3 | B12: ='36-Month Forecast'!AO121 | C12: ='36-Month Forecast'!AO255 | D12: ='36-Month Forecast'!AO389
A13: Net operating result, year 1 | B13: ='36-Month Forecast'!AM126 | C13: ='36-Month Forecast'!AM260 | D13: ='36-Month Forecast'!AM394 | E13: Contribution - ads - operating costs - wave fixed costs
A14: Net operating result, year 2 | B14: ='36-Month Forecast'!AN126 | C14: ='36-Month Forecast'!AN260 | D14: ='36-Month Forecast'!AN394
A15: Net operating result, year 3 | B15: ='36-Month Forecast'!AO126 | C15: ='36-Month Forecast'!AO260 | D15: ='36-Month Forecast'!AO394
A16: One-time costs over 36 months (startup + wave launch + retail readiness) | B16: ='36-Month Forecast'!AP128+'36-Month Forecast'!AP129 | C16: ='36-Month Forecast'!AP262+'36-Month Forecast'!AP263 | D16: ='36-Month Forecast'!AP396+'36-Month Forecast'!AP397 | E16: Startup Costs; Retail Readiness Costs
A17: Inventory purchases over 36 months (board-book print runs) | B17: ='36-Month Forecast'!AP136 | C17: ='36-Month Forecast'!AP270 | D17: ='36-Month Forecast'!AP404 | E17: Sized from pre-sale orders
A18: Cumulative net result after one-time costs, month 36 | B18: ='36-Month Forecast'!AL131 | C18: ='36-Month Forecast'!AL265 | D18: ='36-Month Forecast'!AL399
A20: Cash and break-even
A21: Break-even: trailing-12-month result >= 0 from | B21: ='Break-even'!B8 | C21: ='Break-even'!C8 | D21: ='Break-even'!D8 | E21: Headline measure (Break-even tab)
A22: First month with a monthly operating result >= 0 | B22: ='Break-even'!B10 | C22: ='Break-even'!C10 | D22: ='Break-even'!D10
A23: Founder capital needed through month 36 (funding need) | B23: ='Break-even'!B13 | C23: ='Break-even'!C13 | D23: ='Break-even'!D13 | E23: Cash Flow: cumulative founder capital
A24: ...of which by Sep 2027 (month 12) | B24: ='Break-even'!B14 | C24: ='Break-even'!C14 | D24: ='Break-even'!D14
A25: Self-funding from (no founder capital after this month) | B25: ='Break-even'!B18 | C25: ='Break-even'!C18 | D25: ='Break-even'!D18
A26: Household-money cap passed in (placeholder cap) | B26: ='Break-even'!B20 | C26: ='Break-even'!C20 | D26: ='Break-even'!D20 | E26: Hard stop and re-forecast
A27: Total cash at month 36 (operating + tax reserve) | B27: ='Cash Flow'!AL32 | C27: ='Cash Flow'!AL63 | D27: ='Cash Flow'!AL94
A28: Operating balance vs 3-month reserve target, month 36 | B28: ='Cash Flow'!AL35 | C28: ='Cash Flow'!AL66 | D28: ='Cash Flow'!AL97 | E28: ops/ROUTINE.md reserve target
A30: Volume, anchors and mix
A31: Digital units per product per month at full ramp (site + Etsy + MoR) | B31: ='Assumptions'!$C$122*'Assumptions'!$C$123+'Assumptions'!$C$131*'Assumptions'!$C$132+'Assumptions'!$C$155*'Assumptions'!$C$156 | C31: ='Assumptions'!$D$122*'Assumptions'!$D$123+'Assumptions'!$D$131*'Assumptions'!$D$132+'Assumptions'!$D$155*'Assumptions'!$D$156 | D31: ='Assumptions'!$E$122*'Assumptions'!$E$123+'Assumptions'!$E$131*'Assumptions'!$E$132+'Assumptions'!$E$155*'Assumptions'!$E$156 | E31: Section 1.5 anchors: floor 2.5, Low 10, Base 30, breakout 75
A32: Orders, year 1 | B32: ='36-Month Forecast'!AM116 | C32: ='36-Month Forecast'!AM250 | D32: ='36-Month Forecast'!AM384
A33: Orders, year 3 | B33: ='36-Month Forecast'!AO116 | C33: ='36-Month Forecast'!AO250 | D33: ='36-Month Forecast'!AO384
A34: ...of which Etsy orders, year 3 | B34: ='36-Month Forecast'!AO34 | C34: ='36-Month Forecast'!AO168 | D34: ='36-Month Forecast'!AO302 | E34: Compare: strongest routine-card shop, 2,189 lifetime sales (DEMAND-CHECK)
A35: Orders in month 36 | B35: ='36-Month Forecast'!AL116 | C35: ='36-Month Forecast'!AL250 | D35: ='36-Month Forecast'!AL384
A36: Average gross sale per order, year 3 | B36: =IF('36-Month Forecast'!AO116=0,0,'36-Month Forecast'!AO120/'36-Month Forecast'!AO116) | C36: =IF('36-Month Forecast'!AO250=0,0,'36-Month Forecast'!AO254/'36-Month Forecast'!AO250) | D36: =IF('36-Month Forecast'!AO384=0,0,'36-Month Forecast'!AO388/'36-Month Forecast'!AO384)
A37: Email subscribers at month 36 | B37: ='36-Month Forecast'!AL114 | C37: ='36-Month Forecast'!AL248 | D37: ='36-Month Forecast'!AL382
A38: Share of 36-month contribution from digital (site, Etsy, MoR, course) | B38: =IF('36-Month Forecast'!AP121=0,0,('36-Month Forecast'!AP28+'36-Month Forecast'!AP38+'36-Month Forecast'!AP68+'36-Month Forecast'!AP78)/'36-Month Forecast'!AP121) | C38: =IF('36-Month Forecast'!AP255=0,0,('36-Month Forecast'!AP162+'36-Month Forecast'!AP172+'36-Month Forecast'!AP202+'36-Month Forecast'!AP212)/'36-Month Forecast'!AP255) | D38: =IF('36-Month Forecast'!AP389=0,0,('36-Month Forecast'!AP296+'36-Month Forecast'!AP306+'36-Month Forecast'!AP336+'36-Month Forecast'!AP346)/'36-Month Forecast'!AP389)
A39: Share from print-on-demand books (KDP, IngramSpark) | B39: =IF('36-Month Forecast'!AP121=0,0,('36-Month Forecast'!AP48+'36-Month Forecast'!AP58)/'36-Month Forecast'!AP121) | C39: =IF('36-Month Forecast'!AP255=0,0,('36-Month Forecast'!AP182+'36-Month Forecast'!AP192)/'36-Month Forecast'!AP255) | D39: =IF('36-Month Forecast'!AP389=0,0,('36-Month Forecast'!AP316+'36-Month Forecast'!AP326)/'36-Month Forecast'!AP389)
A40: Share from the board book (gated option; 0 in base) | B40: =IF('36-Month Forecast'!AP121=0,0,'36-Month Forecast'!AP88/'36-Month Forecast'!AP121) | C40: =IF('36-Month Forecast'!AP255=0,0,'36-Month Forecast'!AP222/'36-Month Forecast'!AP255) | D40: =IF('36-Month Forecast'!AP389=0,0,'36-Month Forecast'!AP356/'36-Month Forecast'!AP389)
A41: Share from the school/group wave (overlay only; 0 in base) | B41: =IF('36-Month Forecast'!AP121=0,0,'36-Month Forecast'!AP99/'36-Month Forecast'!AP121) | C41: =IF('36-Month Forecast'!AP255=0,0,'36-Month Forecast'!AP233/'36-Month Forecast'!AP255) | D41: =IF('36-Month Forecast'!AP389=0,0,'36-Month Forecast'!AP367/'36-Month Forecast'!AP389)
A42: Share from retail and wholesale (0 in base) | B42: =IF('36-Month Forecast'!AP121=0,0,'36-Month Forecast'!AP109/'36-Month Forecast'!AP121) | C42: =IF('36-Month Forecast'!AP255=0,0,'36-Month Forecast'!AP243/'36-Month Forecast'!AP255) | D42: =IF('36-Month Forecast'!AP389=0,0,'36-Month Forecast'!AP377/'36-Month Forecast'!AP389)
A43: Board-book pre-sale copies (only if the board book is switched on) | B43: ='36-Month Forecast'!$B$12 | C43: ='36-Month Forecast'!$B$146 | D43: ='36-Month Forecast'!$B$280 | E43: Gated option
A44: ...go line: copies needed to fund the planned run | B44: ='36-Month Forecast'!$B$13 | C44: ='36-Month Forecast'!$B$147 | D44: ='36-Month Forecast'!$B$281 | E44: Below this line: refund, keep the POD paperback
...

Sheet Assumptions
A1: Assumptions: every input in the model
A2: Blue = editable input. Yellow fill = key scenario lever. Black = formula. Green = link to another tab. Status: Repo = figure found in a repository file (most are themselves marked UNVERIFIED there); Assumption = planning input chosen for this model; [VERIFY] = outside fact not in the repo, check before relying on it.
A5: ID | B5: Input | C5: Value / Conservative | D5: Expected | E5: Strong | F5: Unit | G5: Source / basis | H5: Status
A7: 1. General settings
A8: start | B8: Model start month (month 1; costs start here) | C8: 46296 | F8: month | G8: Plan dated Sept 28, 2026. Setup costs (trademark, copyright, attorneys) begin in October 2026. | H8: Repo
A9: first_sale | B9: First month any listing can take money (Gate A met) | C9: 3 | F9: month # | G9: Gate A (section 5.12): business bank account open, employment counsel's go-ahead, GL insurance bound and the publish safeguards built. As of Sept 28, 2026 none is done, so the model assumes Gate A by the end of Nov 2026 and first sales in Dec 2026 (month 3). Each month of slip moves every channel back one month. | H9: Assumption
A10: pos | B10: Cost position inside every Low-High range (0 = low, 1 = high) | C10: 0 | F10: 0-1 | G10: Base plan = lean path: low-end quotes (0). Mid-point (0.5) and high end (1) are shown as sensitivities in section 3.9. Drives the Model column on Startup Costs, Monthly Operating Costs and Retail Readiness Costs. | H10: Assumption
A11: ramp | B11: Months for a new listing to reach full sales rate (review ramp) | C11: 6 | F11: months | G11: A new faceless shop starts with zero reviews against incumbents with 2,000-11,000 (marketing/DEMAND-CHECK.md, 'One honest warning'). | H11: Assumption
A12: mdtax | B12: Maryland sales tax on direct (own-site) sales | C12: 0.06 | F12: % of price | G12: commerce/storefront-setup-guide.md A3 (UNVERIFIED). Collected on top of price and remitted: pass-through, never counted as revenue. | H12: Repo [VERIFY]
A13: refund | B13: Refund and chargeback allowance, direct digital sales | C13: 0.02 | F13: % of price | G13: ops/GAPS-ROUND-2.md G2-12: first refund request under about $15 is refunded automatically. | H13: Assumption
A14: refund_course | B14: Refund allowance, 30-Day Screen Reset (money-back guarantee) | C14: 0.05 | F14: % of price | G14: DEMAND-CHECK course row: 'Add a money-back guarantee'. | H14: Assumption
A15: taxres | B15: Tax reserve (% of cumulative profit to date, after one-time costs) | C15: 0.25 | F15: % | G15: finance/TAX-AUTOPILOT.md §2: accountant picks the rate; 25-30% is common. Reserved only against cumulative profit, because a single-member LLC's losses pass through to the founder's return; the accountant sets the §195 startup-cost treatment. | H15: Repo range
A16: open | B16: Opening cash in the business account | C16: 0 | F16: $ | G16: finance/BANKING.md: the Chase checking account is closed; a new no-fee account opens empty. | H16: Repo
A17: owner | B17: Planned owner capital contribution in month 1 (the forecast adds any further top-up needed) | C17: 0 | F17: $ | G17: Cash Flow adds a founder top-up in any month the operating account would go below zero, so the funding need is always visible. | H17: Assumption
A18: card | B18: Existing balance on the Chase business card (an LLC liability), paid in month 1 | C18: 0 | F18: $ | G18: finance/BANKING.md: the Chase business card is still open. Balance not in the repo: founder to enter. | H18: Founder to enter
A19: cap | B19: Household-money cap: most founder capital the business may take (placeholder) | C19: 12000 | F19: $ | G19: ops/GAPS-ROUND-2.md G2-10 asks the founder to write down a cap and a review date; neither is set. $12,000 is a placeholder only. Hard stop: when cumulative founder capital reaches the cap, all non-deadline spending stops and the plan is re-forecast. | H19: Founder to set
... A21: resmo | B21: Cash reserve target (months of fixed costs) | C21: 3 | F21: months | G21: ops/ROUTINE.md weekly scorecard ('3-month reserve target'); BLIND-SPOTS #20 says 2-3 months. | H21: Repo
A23: 2. Platform fees and royalties (used by Unit Economics)
A24: shop_pct | B24: Shopify Payments card rate | C24: 0.029 | F24: % of price | G24: commerce/storefront-setup-guide.md §1; finance/money-and-tax-setup.md fees table (Basic plan, UNVERIFIED). | H24: Repo [VERIFY]
A25: shop_fix | B25: Shopify Payments fixed fee | C25: 0.3 | F25: $ per order | G25: Same source. | H25: Repo [VERIFY]
A26: etsy_tx | B26: Etsy transaction fee | C26: 0.065 | F26: % of price | G26: storefront-setup-guide §10 (UNVERIFIED). | H26: Repo [VERIFY]
A27: etsy_pay | B27: Etsy payment processing (US) | C27: 0.03 | F27: % of price | G27: Same source. | H27: Repo [VERIFY]
A28: etsy_payfix | B28: Etsy payment processing fixed fee | C28: 0.25 | F28: $ per order | G28: Same source. | H28: Repo [VERIFY]
A29: etsy_list | B29: Etsy listing fee (renews on each sale) | C29: 0.2 | F29: $ per sale | G29: Same source. | H29: Repo [VERIFY]
A30: etsy_oa | B30: Etsy Offsite Ads fee when an ad drives the sale | C30: 0.15 | F30: % of price | G30: Same source: 15%, or 12% and mandatory above $10,000 in 12 months. | H30: Repo [VERIFY]
A31: etsy_oashare | B31: Share of Etsy sales that come through Offsite Ads | C31: 0.1 | F31: % of Etsy sales | G31: No data yet; check the Etsy statement after 90 days. | H31: Assumption
A32: kdp_roy | B32: KDP paperback royalty rate (list price $9.99 or more) | C32: 0.6 | F32: % of list | G32: storefront-setup-guide §6: 60% at $9.99+ since June 10, 2025 (UNVERIFIED). | H32: Repo [VERIFY]
A33: kdp_base | B33: KDP print cost: fixed part | C33: 1 | F33: $ per copy | G33: products/*/listing.json price_notes: $1.00 + $0.07/page premium color. | H33: Repo [VERIFY]
A34: kdp_color | B34: KDP print cost: premium color, per page | C34: 0.07 | F34: $ per page | G34: Same source. KDP may price short color books at a flat rate; confirm in the calculator. | H34: Repo [VERIFY]
A35: kdp_bw_flat | B35: KDP print cost: black-and-white paperback, 24-108 pages (flat) | C35: 2.3 | F35: $ per copy | G35: products/guide-100-plays/listing.json: KDP's flat $2.30 for 24-108 B/W pages (82-page, 8 x 10 in book). Check whether 8 x 10 counts as large trim, which may cost more. | H35: Repo [VERIFY]
... A54: tee_pod | B54: Adult tee: POD base cost incl. print | C54: 12.5 | F54: $ per unit | G54: Not in the repo; shipping assumed charged to the buyer. Tee is weight 0 until trademark clearance (Wave 3). | H54: [VERIFY]
A56: 3. Physical products: board book (gated option) and retail stock
A57: bb_price | B57: Board book retail price (Up! Go! More!) | C57: 12.99 | F57: $ | G57: DEMAND-CHECK §4 rule 9; board-up-go-more/listing.json. | H57: Repo
A58: min_run | B58: Planned first offset run | C58: 1000 | F58: copies | G58: BLIND-SPOTS #11: quotes at 500, 1,000 and 2,500 copies (5,000 added for a retail edition). | H58: Assumption
A59: ID | B59: Offset quote table (run size -> print cost per copy) | C59: Run size | D59: Cost per copy | F59: Unit | G59: Source / basis | H59: Status
A60: quote_500 | B60: Quote at 500 copies | C60: 500 | D60: 5.5 | F60: $ per copy | G60: Above the BLIND-SPOTS range at a short run; no quote exists. | H60: Assumption [VERIFY]
A61: quote_1000 | B61: Quote at 1,000 copies | C61: 1000 | D61: 4 | F61: $ per copy | G61: BLIND-SPOTS #11: $1.80-$4 at 1,000-3,000 copies; a 1,000-copy run sits at the high end. | H61: Repo [VERIFY]
A62: quote_2500 | B62: Quote at 2,500 copies | C62: 2500 | D62: 2.2 | F62: $ per copy | G62: Interpolated toward $1.80 at 3,000 copies (BLIND-SPOTS #11). | H62: Assumption [VERIFY]
A63: quote_5000 | B63: Quote at 5,000 copies | C63: 5000 | D63: 1.6 | F63: $ per copy | G63: Below the repo range; retail-edition planning figure only. | H63: Assumption [VERIFY]
A64: bb_print | B64: Offset print cost per copy used in model (quote at the planned run size) | C64: =LOOKUP('Assumptions'!$C$58,'Assumptions'!$C$60:$C$63,'Assumptions'!$D$60:$D$63) | F64: $ per copy | G64: Largest quoted run size at or below the planned run. | H64: Formula
...

Sheet Unit Economics
A1: Unit economics: net to AlphaPlay LLC per unit, by product and channel
A2: Net per unit = Price x (1 - platform % - payment % - refund %) - fixed fees - print/POD/landed cost - fulfilment. Sales tax and VAT are pass-through and never counted as revenue. Blue prices are editable; other channels link to them.
A5: Channel code | B5: Product | C5: Channel / route | D5: Wave | E5: Price to customer ($) | F5: Platform / marketplace fee % | G5: Platform fixed fee ($/unit) | H5: Payment processing % | I5: Payment fixed fee ($) | J5: Refund / deduction allowance % | K5: Print, POD or landed cost ($/unit) | L5: Fulfilment ($/unit) | M5: Net per unit ($) | N5: Net margin % | O5: Inventory cost paid up front ($/unit) | P5: Mix weight in channel | Q5: Sales tax / VAT handling | R5: Source / notes
A6: SITE | B6: Visual routine cards (200+ editable; 0-5 set at launch, 5-12 set added free when G1 clears) | C6: Own site (Shopify) | D6: 1 | E6: 6.5 | F6: 0 | G6: 0 | H6: ='Assumptions'!$C$24 | I6: ='Assumptions'!$C$25 | J6: ='Assumptions'!$C$13 | K6: 0 | L6: 0 | M6: =E6*(1-F6-H6-J6)-G6-I6-K6-L6 | N6: =IF(E6=0,0,M6/E6) | O6: 0 | P6: 25 | Q6: Shopify Tax adds MD 6% at checkout; AlphaPlay remits (pass-through, not revenue) | R6: Everyday price $6.50 under BRAND.md 'Honest pricing' (no anchor or permanent sale).
A7: SITE | B7: "I'm bored" play cards (150, age-banded) | C7: Own site (Shopify) | D7: 1 | E7: 6.5 | F7: 0 | G7: 0 | H7: ='Assumptions'!$C$24 | I7: ='Assumptions'!$C$25 | J7: ='Assumptions'!$C$13 | K7: 0 | L7: 0 | M7: =E7*(1-F7-H7-J7)-G7-I7-K7-L7 | N7: =IF(E7=0,0,M7/E7) | O7: 0 | P7: 15 | Q7: Shopify Tax adds MD 6% at checkout; AlphaPlay remits (pass-through, not revenue) | R7: DEMAND-CHECK §3 #2.
A8: SITE | B8: Play-First Family Kit (2-5 pages at launch; 5-12 pages added free when G1 clears) | C8: Own site (Shopify) | D8: 1 | E8: 11 | F8: 0 | G8: 0 | H8: ='Assumptions'!$C$24 | I8: ='Assumptions'!$C$25 | J8: ='Assumptions'!$C$13 | K8: 0 | L8: 0 | M8: =E8*(1-F8-H8-J8)-G8-I8-K8-L8 | N8: =IF(E8=0,0,M8/E8) | O8: 0 | P8: 20 | Q8: Shopify Tax adds MD 6% at checkout; AlphaPlay remits (pass-through, not revenue) | R8: DEMAND-CHECK §3 #3.
A9: SITE | B9: Toddler busy book printable (120-150 pages) | C9: Own site (Shopify) | D9: 1 | E9: 11.99 | F9: 0 | G9: 0 | H9: ='Assumptions'!$C$24 | I9: ='Assumptions'!$C$25 | J9: ='Assumptions'!$C$13 | K9: 0 | L9: 0 | M9: =E9*(1-F9-H9-J9)-G9-I9-K9-L9 | N9: =IF(E9=0,0,M9/E9) | O9: 0 | P9: 18 | Q9: Shopify Tax adds MD 6% at checkout; AlphaPlay remits (pass-through, not revenue) | R9: Everyday price $11.99 under BRAND.md 'Honest pricing' (DEMAND-CHECK §3 #4 street level).
A10: SITE | B10: 100 Screen-Free Plays (PDF) | C10: Own site (Shopify) | D10: 1 | E10: 9.99 | F10: 0 | G10: 0 | H10: ='Assumptions'!$C$24 | I10: ='Assumptions'!$C$25 | J10: ='Assumptions'!$C$13 | K10: 0 | L10: 0 | M10: =E10*(1-F10-H10-J10)-G10-I10-K10-L10 | N10: =IF(E10=0,0,M10/E10) | O10: 0 | P10: 10 | Q10: Shopify Tax adds MD 6% at checkout; AlphaPlay remits (pass-through, not revenue) | R10: DEMAND-CHECK §3 #5.
A11: SITE | B11: Screen-Free Car Ride & Waiting Pack | C11: Own site (Shopify) | D11: 1 | E11: 6 | F11: 0 | G11: 0 | H11: ='Assumptions'!$C$24 | I11: ='Assumptions'!$C$25 | J11: ='Assumptions'!$C$13 | K11: 0 | L11: 0 | M11: =E11*(1-F11-H11-J11)-G11-I11-K11-L11 | N11: =IF(E11=0,0,M11/E11) | O11: 0 | P11: 5 | Q11: Shopify Tax adds MD 6% at checkout; AlphaPlay remits (pass-through, not revenue) | R11: DEMAND-CHECK §3 first alternate.
A12: SITE | B12: First-words flash cards (printable) | C12: Own site (Shopify) | D12: 1 | E12: 6.99 | F12: 0 | G12: 0 | H12: ='Assumptions'!$C$24 | I12: ='Assumptions'!$C$25 | J12: ='Assumptions'!$C$13 | K12: 0 | L12: 0 | M12: =E12*(1-F12-H12-J12)-G12-I12-K12-L12 | N12: =IF(E12=0,0,M12/E12) | O12: 0 | P12: 3 | Q12: Shopify Tax adds MD 6% at checkout; AlphaPlay remits (pass-through, not revenue) | R12: DEMAND-CHECK §2 #3.
A13: SITE | B13: ALPHAPLAY Spelling Games printable (G1; trademark-use product) | C13: Own site (Shopify) | D13: 1 | E13: 6 | F13: 0 | G13: 0 | H13: ='Assumptions'!$C$24 | I13: ='Assumptions'!$C$25 | J13: ='Assumptions'!$C$13 | K13: 0 | L13: 0 | M13: =E13*(1-F13-H13-J13)-G13-I13-K13-L13 | N13: =IF(E13=0,0,M13/E13) | O13: 0 | P13: 0 | Q13: Shopify Tax adds MD 6% at checkout; AlphaPlay remits (pass-through, not revenue) | R13: ops/QUEUE.md #1. Weight 0: its job is to protect the mark, it is G1 pending counsel, and the demand check found no sales evidence.
A14: SITE | B14: Adult tee (POD, 2-3 cleared designs max) | C14: Own site (Shopify) + POD partner | D14: 1 | E14: 27 | F14: 0 | G14: 0 | H14: ='Assumptions'!$C$24 | I14: ='Assumptions'!$C$25 | J14: ='Assumptions'!$C$13 | K14: ='Assumptions'!$C$54 | L14: 0 | M14: =E14*(1-F14-H14-J14)-G14-I14-K14-L14 | N14: =IF(E14=0,0,M14/E14) | O14: 0 | P14: 0 | Q14: Shopify Tax adds MD 6% at checkout; AlphaPlay remits (pass-through, not revenue) | R14: DEMAND-CHECK tees row: $27. Weight 0 until the designs clear trademark review (Wave 3).
A15: ETSY | B15: Visual routine cards (200+ editable; 0-5 set at launch, 5-12 set added free when G1 clears) | C15: Etsy | D15: 1 | E15: =E6 | F15: ='Assumptions'!$C$26+'Assumptions'!$C$30*'Assumptions'!$C$31 | G15: ='Assumptions'!$C$29 | H15: ='Assumptions'!$C$27 | I15: ='Assumptions'!$C$28 | J15: ='Assumptions'!$C$13 | K15: 0 | L15: 0 | M15: =E15*(1-F15-H15-J15)-G15-I15-K15-L15 | N15: =IF(E15=0,0,M15/E15) | O15: 0 | P15: 25 | Q15: Etsy is marketplace facilitator: collects and remits | R15: Price linked to the own-site row.
A16: ETSY | B16: "I'm bored" play cards (150, age-banded) | C16: Etsy | D16: 1 | E16: =E7 | F16: ='Assumptions'!$C$26+'Assumptions'!$C$30*'Assumptions'!$C$31 | G16: ='Assumptions'!$C$29 | H16: ='Assumptions'!$C$27 | I16: ='Assumptions'!$C$28 | J16: ='Assumptions'!$C$13 | K16: 0 | L16: 0 | M16: =E16*(1-F16-H16-J16)-G16-I16-K16-L16 | N16: =IF(E16=0,0,M16/E16) | O16: 0 | P16: 15 | Q16: Etsy is marketplace facilitator: collects and remits | R16: Price linked to the own-site row.
A17: ETSY | B17: Play-First Family Kit (2-5 pages at launch; 5-12 pages added free when G1 clears) | C17: Etsy | D17: 1 | E17: =E8 | F17: ='Assumptions'!$C$26+'Assumptions'!$C$30*'Assumptions'!$C$31 | G17: ='Assumptions'!$C$29 | H17: ='Assumptions'!$C$27 | I17: ='Assumptions'!$C$28 | J17: ='Assumptions'!$C$13 | K17: 0 | L17: 0 | M17: =E17*(1-F17-H17-J17)-G17-I17-K17-L17 | N17: =IF(E17=0,0,M17/E17) | O17: 0 | P17: 20 | Q17: Etsy is marketplace facilitator: collects and remits | R17: Price linked to the own-site row.
A18: ETSY | B18: Toddler busy book printable (120-150 pages) | C18: Etsy | D18: 1 | E18: =E9 | F18: ='Assumptions'!$C$26+'Assumptions'!$C$30*'Assumptions'!$C$31 | G18: ='Assumptions'!$C$29 | H18: ='Assumptions'!$C$27 | I18: ='Assumptions'!$C$28 | J18: ='Assumptions'!$C$13 | K18: 0 | L18: 0 | M18: =E18*(1-F18-H18-J18)-G18-I18-K18-L18 | N18: =IF(E18=0,0,M18/E18) | O18: 0 | P18: 18 | Q18: Etsy is marketplace facilitator: collects and remits | R18: Price linked to the own-site row.
A19: ETSY | B19: 100 Screen-Free Plays (PDF) | C19: Etsy | D19: 1 | E19: =E10 | F19: ='Assumptions'!$C$26+'Assumptions'!$C$30*'Assumptions'!$C$31 | G19: ='Assumptions'!$C$29 | H19: ='Assumptions'!$C$27 | I19: ='Assumptions'!$C$28 | J19: ='Assumptions'!$C$13 | K19: 0 | L19: 0 | M19: =E19*(1-F19-H19-J19)-G19-I19-K19-L19 | N19: =IF(E19=0,0,M19/E19) | O19: 0 | P19: 10 | Q19: Etsy is marketplace facilitator: collects and remits | R19: Price linked to the own-site row.
A20: ETSY | B20: Screen-Free Car Ride & Waiting Pack | C20: Etsy | D20: 1 | E20: =E11 | F20: ='Assumptions'!$C$26+'Assumptions'!$C$30*'Assumptions'!$C$31 | G20: ='Assumptions'!$C$29 | H20: ='Assumptions'!$C$27 | I20: ='Assumptions'!$C$28 | J20: ='Assumptions'!$C$13 | K20: 0 | L20: 0 | M20: =E20*(1-F20-H20-J20)-G20-I20-K20-L20 | N20: =IF(E20=0,0,M20/E20) | O20: 0 | P20: 5 | Q20: Etsy is marketplace facilitator: collects and remits | R20: Price linked to the own-site row.
A21: ETSY | B21: First-words flash cards (printable) | C21: Etsy | D21: 1 | E21: =E12 | F21: ='Assumptions'!$C$26+'Assumptions'!$C$30*'Assumptions'!$C$31 | G21: ='Assumptions'!$C$29 | H21: ='Assumptions'!$C$27 | I21: ='Assumptions'!$C$28 | J21: ='Assumptions'!$C$13 | K21: 0 | L21: 0 | M21: =E21*(1-F21-H21-J21)-G21-I21-K21-L21 | N21: =IF(E21=0,0,M21/E21) | O21: 0 | P21: 3 | Q21: Etsy is marketplace facilitator: collects and remits | R21: Price linked to the own-site row.
A22: ETSY | B22: ALPHAPLAY Spelling Games printable (G1; trademark-use product) | C22: Etsy | D22: 1 | E22: =E13 | F22: ='Assumptions'!$C$26+'Assumptions'!$C$30*'Assumptions'!$C$31 | G22: ='Assumptions'!$C$29 | H22: ='Assumptions'!$C$27 | I22: ='Assumptions'!$C$28 | J22: ='Assumptions'!$C$13 | K22: 0 | L22: 0 | M22: =E22*(1-F22-H22-J22)-G22-I22-K22-L22 | N22: =IF(E22=0,0,M22/E22) | O22: 0 | P22: 0 | Q22: Etsy is marketplace facilitator: collects and remits | R22: Price linked to the own-site row.
A23: MOR | B23: Visual routine cards (200+ editable; 0-5 set at launch, 5-12 set added free when G1 clears) | C23: Gumroad (merchant of record), buyers outside the US | D23: 1-2 | E23: =E6 | F23: ='Assumptions'!$C$40 | G23: ='Assumptions'!$C$41 | H23: 0 | I23: 0 | J23: ='Assumptions'!$C$13 | K23: 0 | L23: 0 | M23: =E23*(1-F23-H23-J23)-G23-I23-K23-L23 | N23: =IF(E23=0,0,M23/E23) | O23: 0 | P23: 25 | Q23: Merchant of record collects and remits US sales tax and EU/UK VAT | R23: International plan: one MoR for international digital sales.
A24: MOR | B24: "I'm bored" play cards (150, age-banded) | C24: Gumroad (merchant of record), buyers outside the US | D24: 1-2 | E24: =E7 | F24: ='Assumptions'!$C$40 | G24: ='Assumptions'!$C$41 | H24: 0 | I24: 0 | J24: ='Assumptions'!$C$13 | K24: 0 | L24: 0 | M24: =E24*(1-F24-H24-J24)-G24-I24-K24-L24 | N24: =IF(E24=0,0,M24/E24) | O24: 0 | P24: 15 | Q24: Merchant of record collects and remits US sales tax and EU/UK VAT | R24: International plan: one MoR for international digital sales.
A25: MOR | B25: Play-First Family Kit (2-5 pages at launch; 5-12 pages added free when G1 clears) | C25: Gumroad (merchant of record), buyers outside the US | D25: 1-2 | E25: =E8 | F25: ='Assumptions'!$C$40 | G25: ='Assumptions'!$C$41 | H25: 0 | I25: 0 | J25: ='Assumptions'!$C$13 | K25: 0 | L25: 0 | M25: =E25*(1-F25-H25-J25)-G25-I25-K25-L25 | N25: =IF(E25=0,0,M25/E25) | O25: 0 | P25: 20 | Q25: Merchant of record collects and remits US sales tax and EU/UK VAT | R25: International plan: one MoR for international digital sales.
A26: MOR | B26: Toddler busy book printable (120-150 pages) | C26: Gumroad (merchant of record), buyers outside the US | D26: 1-2 | E26: =E9 | F26: ='Assumptions'!$C$40 | G26: ='Assumptions'!$C$41 | H26: 0 | I26: 0 | J26: ='Assumptions'!$C$13 | K26: 0 | L26: 0 | M26: =E26*(1-F26-H26-J26)-G26-I26-K26-L26 | N26: =IF(E26=0,0,M26/E26) | O26: 0 | P26: 18 | Q26: Merchant of record collects and remits US sales tax and EU/UK VAT | R26: International plan: one MoR for international digital sales.
A27: MOR | B27: 100 Screen-Free Plays (PDF) | C27: Gumroad (merchant of record), buyers outside the US | D27: 1-2 | E27: =E10 | F27: ='Assumptions'!$C$40 | G27: ='Assumptions'!$C$41 | H27: 0 | I27: 0 | J27: ='Assumptions'!$C$13 | K27: 0 | L27: 0 | M27: =E27*(1-F27-H27-J27)-G27-I27-K27-L27 | N27: =IF(E27=0,0,M27/E27) | O27: 0 | P27: 10 | Q27: Merchant of record collects and remits US sales tax and EU/UK VAT | R27: International plan: one MoR for international digital sales.
A28: KDP | B28: 100 Screen-Free Plays (paperback, B/W interior) | C28: Amazon KDP | D28: 1 | E28: 16.99 | F28: =1-'Assumptions'!$C$32 | G28: 0 | H28: 0 | I28: 0 | J28: 0 | K28: ='Assumptions'!$C$35 | L28: 0 | M28: =E28*(1-F28-H28-J28)-G28-I28-K28-L28 | N28: =IF(E28=0,0,M28/E28) | O28: 0 | P28: 50 | Q28: Amazon is the retailer; royalty only, no sales tax for AlphaPlay | R28: guide-100-plays/listing.json: $16.99; KDP flat $2.30 B/W print; net about $7.89 [VERIFY].
A29: KDP | B29: The Day the Tablet Slept (paperback) | C29: Amazon KDP | D29: 1 | E29: 11.99 | F29: =1-'Assumptions'!$C$32 | G29: 0 | H29: 0 | I29: 0 | J29: 0 | K29: ='Assumptions'!$C$33+'Assumptions'!$C$34*'Assumptions'!$C$36 | L29: 0 | M29: =E29*(1-F29-H29-J29)-G29-I29-K29-L29 | N29: =IF(E29=0,0,M29/E29) | O29: 0 | P29: 20 | Q29: Amazon is the retailer; royalty only, no sales tax for AlphaPlay | R29: picture-tablet-slept/listing.json: $11.99; about $3.95/copy royalty.
A30: KDP | B30: Up! Go! More! (talk-along paperback) | C30: Amazon KDP | D30: 1 | E30: 11.99 | F30: =1-'Assumptions'!$C$32 | G30: 0 | H30: 0 | I30: 0 | J30: 0 | K30: ='Assumptions'!$C$33+'Assumptions'!$C$34*'Assumptions'!$C$36 | L30: 0 | M30: =E30*(1-F30-H30-J30)-G30-I30-K30-L30 | N30: =IF(E30=0,0,M30/E30) | O30: 0 | P30: 30 | Q30: Amazon is the retailer; royalty only, no sales tax for AlphaPlay | R30: board-up-go-more/listing.json: $11.99 paperback edition sells now with no inventory.
A31: INGRAM | B31: 100 Screen-Free Plays (paperback via Ingram) | C31: IngramSpark (same ISBN; KDP Expanded Distribution off) | D31: 2 | E31: =E28 | F31: ='Assumptions'!$C$37 | G31: 0 | H31: 0 | I31: 0 | J31: 0 | K31: ='Assumptions'!$C$35 | L31: 0 | M31: =E31*(1-F31-H31-J31)-G31-I31-K31-L31 | N31: =IF(E31=0,0,M31/E31) | O31: 0 | P31: 50 | Q31: Retailer collects; AlphaPlay receives publisher compensation | R31: storefront-setup-guide Part D. Print cost proxy = KDP flat B/W rate [VERIFY].
A32: INGRAM | B32: Up! Go! More! (paperback via Ingram) | C32: IngramSpark | D32: 2 | E32: =E30 | F32: ='Assumptions'!$C$37 | G32: 0 | H32: 0 | I32: 0 | J32: 0 | K32: ='Assumptions'!$C$39 | L32: 0 | M32: =E32*(1-F32-H32-J32)-G32-I32-K32-L32 | N32: =IF(E32=0,0,M32/E32) | O32: 0 | P32: 50 | Q32: Retailer collects; AlphaPlay receives publisher compensation | R32: board-up-go-more/listing.json channels.
A33: INGRAM | B33: The Day the Tablet Slept (hardcover; gated) | C33: IngramSpark | D33: gated | E33: 19.99 | F33: ='Assumptions'!$C$37 | G33: 0 | H33: 0 | I33: 0 | J33: 0 | K33: ='Assumptions'!$C$38 | L33: 0 | M33: =E33*(1-F33-H33-J33)-G33-I33-K33-L33 | N33: =IF(E33=0,0,M33/E33) | O33: 0 | P33: 0 | Q33: Retailer collects; AlphaPlay receives publisher compensation | R33: picture-tablet-slept/listing.json: turn on only after the paperback sells (demand 'Weak'). Weight 0. Laps Not Apps is not in this channel: it is now a personalized keepsake printed per order (amazon_route 'none-with-reason').
A34: COURSE | B34: 30-Day Screen Reset (written program) | C34: Own site (Shopify) + automated email | D34: 2 | E34: 27 | F34: 0 | G34: 0 | H34: ='Assumptions'!$C$24 | I34: ='Assumptions'!$C$25 | J34: ='Assumptions'!$C$14 | K34: 0 | L34: 0 | M34: =E34*(1-F34-H34-J34)-G34-I34-K34-L34 | N34: =IF(E34=0,0,M34/E34) | O34: 0 | P34: 70 | Q34: Shopify Tax adds MD 6% at checkout; AlphaPlay remits (pass-through, not revenue) | R34: DEMAND-CHECK course row: $27.
A35: COURSE | B35: 30-Day Screen Reset bundle | C35: Own site (Shopify) + automated email | D35: 2 | E35: 49 | F35: 0 | G35: 0 | H35: ='Assumptions'!$C$24 | I35: ='Assumptions'!$C$25 | J35: ='Assumptions'!$C$14 | K35: 0 | L35: 0 | M35: =E35*(1-F35-H35-J35)-G35-I35-K35-L35 | N35: =IF(E35=0,0,M35/E35) | O35: 0 | P35: 30 | Q35: Shopify Tax adds MD 6% at checkout; AlphaPlay remits (pass-through, not revenue) | R35: DEMAND-CHECK course row: $49 bundle.
A36: BOARD | B36: Up! Go! More! board book | C36: Own site; offset stock at a 3PL | D36: gated | E36: ='Assumptions'!$C$57 | F36: 0 | G36: 0 | H36: ='Assumptions'!$C$24 | I36: ='Assumptions'!$C$25 | J36: ='Assumptions'!$C$13 | K36: ='Assumptions'!$C$66 | L36: ='Assumptions'!$C$67+'Assumptions'!$C$48 | M36: =E36*(1-F36-H36-J36)-G36-I36-K36-L36 | N36: =IF(E36=0,0,M36/E36) | O36: ='Assumptions'!$C$66 | P36: 60 | Q36: Shopify Tax adds MD 6% at checkout; AlphaPlay remits (pass-through, not revenue) | R36: Offset run held and shipped by a 3PL, never the founder (BRAND.md). Pick/pack plus about $2 of postage absorbed.
A37: BOARD | B37: Up! Go! More! board book | C37: Amazon FBA (from the print month; the pre-sale is own-site only) | D37: gated | E37: ='Assumptions'!$C$57 | F37: ='Assumptions'!$C$44 | G37: ='Assumptions'!$C$46 | H37: 0 | I37: 0 | J37: 0 | K37: ='Assumptions'!$C$66 | L37: ='Assumptions'!$C$45+'Assumptions'!$C$47 | M37: =E37*(1-F37-H37-J37)-G37-I37-K37-L37 | N37: =IF(E37=0,0,M37/E37) | O37: ='Assumptions'!$C$66 | P37: 40 | Q37: Amazon collects and remits | R37: AMAZON-AND-RETAIL-ROADMAP A: board books via FBA; closing fee, storage and placement allowance included [VERIFY].
A38: SCHOOL | B38: TPT single resource (e.g., talk brain breaks) | C38: Teachers Pay Teachers | D38: 4 (held) | E38: 5 | F38: =1-'Assumptions'!$C$42 | G38: ='Assumptions'!$C$43 | H38: 0 | I38: 0 | J38: 0 | K38: 0 | L38: 0 | M38: =E38*(1-F38-H38-J38)-G38-I38-K38-L38 | N38: =IF(E38=0,0,M38/E38) | O38: 0 | P38: 40 | Q38: TPT remits as marketplace (UNVERIFIED) | R38: DEMAND-CHECK teacher table: $5 singles; held for counsel.
A39: SCHOOL | B39: Classroom Talk and Play growth bundle | C39: Teachers Pay Teachers | D39: 4 (held) | E39: 22 | F39: =1-'Assumptions'!$C$42 | G39: ='Assumptions'!$C$43 | H39: 0 | I39: 0 | J39: 0 | K39: 0 | L39: 0 | M39: =E39*(1-F39-H39-J39)-G39-I39-K39-L39 | N39: =IF(E39=0,0,M39/E39) | O39: 0 | P39: 20 | Q39: TPT remits as marketplace (UNVERIFIED) | R39: DEMAND-CHECK §2 #11: $22-26.
A40: SCHOOL | B40: Single-classroom license | C40: Direct invoice / Shopify draft order | D40: 4 (held) | E40: 29 | F40: 0 | G40: 0 | H40: ='Assumptions'!$C$24 | I40: ='Assumptions'!$C$25 | J40: 0 | K40: 0 | L40: 0 | M40: =E40*(1-F40-H40-J40)-G40-I40-K40-L40 | N40: =IF(E40=0,0,M40/E40) | O40: 0 | P40: 20 | Q40: Tax-exempt certificate kept on file; otherwise MD 6% | R40: MARKETING-PLAYBOOK School Purchasing Kit: Single Classroom $29.
A41: SCHOOL | B41: Host-it-yourself parent-night kit, single site | C41: Direct invoice / Shopify | D41: 4 (held) | E41: 129 | F41: 0 | G41: 0 | H41: ='Assumptions'!$C$24 | I41: ='Assumptions'!$C$25 | J41: 0 | K41: 0 | L41: 0 | M41: =E41*(1-F41-H41-J41)-G41-I41-K41-L41 | N41: =IF(E41=0,0,M41/E41) | O41: 0 | P41: 2 | Q41: Tax-exempt certificate kept on file; otherwise MD 6% | R41: DEMAND-CHECK: $129 single site. Near-zero weight: no kit sales counts exist and a free leader program competes.
A42: SCHOOL | B42: Host kit, multi-site | C42: Direct invoice / Shopify | D42: 4 (held) | E42: 249 | F42: 0 | G42: 0 | H42: ='Assumptions'!$C$24 | I42: ='Assumptions'!$C$25 | J42: 0 | K42: 0 | L42: 0 | M42: =E42*(1-F42-H42-J42)-G42-I42-K42-L42 | N42: =IF(E42=0,0,M42/E42) | O42: 0 | P42: 0 | Q42: Tax-exempt certificate kept on file; otherwise MD 6% | R42: DEMAND-CHECK: $249 multi-site. Weight 0 until there is evidence.
...

Sheet Startup Costs
A1: Startup costs: one-time items
A2: Model ($) = Low + cost position x (High - Low), using the cost position on Assumptions. Set Include to 0 to drop an item. Recurring items (insurance, domains, subscriptions) live on Monthly Operating Costs.
A5: Item | B5: Category | C5: Low ($) | D5: High ($) | E5: Model ($) | F5: Month incurred (model month #) | G5: Include (1/0) | H5: Source | I5: Status
A6: Trade-name filing, 'Play Before Pixels' (SDAT) | B6: Legal/entity | C6: 25 | D6: 50 | E6: =C6+'Assumptions'!$C$10*(D6-C6) | F6: 1 | G6: 1 | H6: legal/protection/PROTECTION-PLAN.md: $25 ($50 expedited). | I6: Repo
A7: Principal office / resident agent change (SDAT) | B7: Legal/entity | C7: 25 | D7: 50 | E7: =C7+'Assumptions'!$C$10*(D7-C7) | F7: 1 | G7: 1 | H7: PROTECTION-PLAN: $25 ($50 expedited). | I7: Repo
A8: DMCA designated agent registration | B8: Legal/IP | C8: 6 | D8: 6 | E8: =C8+'Assumptions'!$C$10*(D8-C8) | F8: 1 | G8: 1 | H8: PROTECTION-PLAN: $6, renews every 3 years. | I8: Repo
A9: Etsy shop opening fee (may apply) | B9: Channels | C9: 0 | D9: 15 | E9: =C9+'Assumptions'!$C$10*(D9-C9) | F9: 1 | G9: 1 | H9: storefront-setup-guide §10. | I9: Repo [VERIFY]
A10: ISBNs: KDP's free ISBN (founder's decision; a Bowker 10-pack, $295, only if IngramSpark editions are added) | B10: Publishing | C10: 0 | D10: 0 | E10: =C10+'Assumptions'!$C$10*(D10-C10) | F10: 1 | G10: 1 | H10: business/DECISIONS.md 2026-09-28. | I10: Decided
A11: Trademark clearance search + attorney opinion, PLAY BEFORE PIXELS | B11: Legal/IP | C11: 500 | D11: 2500 | E11: =C11+'Assumptions'!$C$10*(D11-C11) | F11: 1 | G11: 1 | H11: legal/DECISION-MEMO.json step 2. | I11: Repo [VERIFY]
A12: USPTO application, PLAY BEFORE PIXELS, classes 16 + 41 | B12: Legal/IP | C12: 700 | D12: 700 | E12: =C12+'Assumptions'!$C$10*(D12-C12) | F12: 2 | G12: 1 | H12: PROTECTION-PLAN #7: $350/class, within 90 days. | I12: Repo
A13: ALPHAPLAY Statement of Use ($150/class) or extension (up to $625) | B13: Legal/IP | C13: 150 | D13: 625 | E13: =C13+'Assumptions'!$C$10*(D13-C13) | F13: 5 | G13: 1 | H13: PROTECTION-PLAN #6: due Mar 8, 2027; target Feb 1, 2027. | I13: Repo
A14: Trademark attorney, ALPHAPLAY filing | B14: Legal/IP | C14: 300 | D14: 1000 | E14: =C14+'Assumptions'!$C$10*(D14-C14) | F14: 4 | G14: 1 | H14: marketing/BLIND-SPOTS.md #9. | I14: Repo
A15: Copyright registrations for pending works (before Nov 11, 2026) | B15: Legal/IP | C15: 360 | D15: 680 | E15: =C15+'Assumptions'!$C$10*(D15-C15) | F15: 2 | G15: 1 | H15: PROTECTION-PLAN: about 8 filings at $45-$85. | I15: Repo
A16: Attorney: IP assignment to the LLC + operating-agreement refresh | B16: Legal/entity | C16: 500 | D16: 2000 | E16: =C16+'Assumptions'!$C$10*(D16-C16) | F16: 3 | G16: 1 | H16: PROTECTION-PLAN #5 (after employment counsel answers). | I16: Repo [VERIFY]
A17: Attorney: Terms of Sale and website legal pages | B17: Legal | C17: 500 | D17: 2500 | E17: =C17+'Assumptions'!$C$10*(D17-C17) | F17: 1 | G17: 1 | H17: PROTECTION-PLAN contracts table; DECISION-MEMO $500-$2,000. | I17: Repo [VERIFY]
... A39: GATED (seasonal calendars): tradition reviewers (4 traditions) | B39: Product | C39: 400 | D39: 1200 | E39: =C39+'Assumptions'!$C$10*(D39-C39) | F39: 14 | G39: 0 | H39: Section 5.4: quote needed; $100-$300 each assumed. | I39: Assumption
A40: Total (included items) | C40: =SUMPRODUCT(C6:C39,$G$6:$G$39) | D40: =SUMPRODUCT(D6:D39,$G$6:$G$39) | E40: =SUMPRODUCT(E6:E39,$G$6:$G$39)
A41: Gated items not in the base plan (total at model cost) | C41: =SUMPRODUCT(C6:C39,1-$G$6:$G$39) | D41: =SUMPRODUCT(D6:D39,1-$G$6:$G$39) | E41: =SUMPRODUCT(E6:E39,1-$G$6:$G$39)
A42: Timing summary
A43: Months 1-3 (Oct-Dec 2026) | E43: =SUMPRODUCT(($F$6:$F$39>=1)*($F$6:$F$39<=3)*$G$6:$G$39*$E$6:$E$39)
A44: Months 4-12 | E44: =SUMPRODUCT(($F$6:$F$39>=4)*($F$6:$F$39<=12)*$G$6:$G$39*$E$6:$E$39)
A45: Year 2 | E45: =SUMPRODUCT(($F$6:$F$39>=13)*($F$6:$F$39<=24)*$G$6:$G$39*$E$6:$E$39)
A46: Year 3 | E46: =SUMPRODUCT(($F$6:$F$39>=25)*($F$6:$F$39<=36)*$G$6:$G$39*$E$6:$E$39)
A48: GATED rows are listed with their trigger and month so nothing in the plan is unpriced; they stay at Include = 0 until the named gate is met. Not included: employment-counsel fees (a personal matter for the founder); board-book illustration, CPSIA testing, 3PL setup and the first run (Retail Readiness Costs).

Sheet Monthly Operating Costs
A1: Monthly operating costs: subscriptions, Claude plan, email platform, connectors, insurance and reserve
A2: Low/High are the amount per billing period (per month for Monthly items, per year for Annual items). Model = Low + cost position x (High - Low). Annual items hit in their start month and every 12 months after. Insurance is shown billed monthly (annual premium / 12).
N3: Year | O3: =INT((O4-1)/12)+1 | P3: =INT((P4-1)/12)+1 | Q3: =INT((Q4-1)/12)+1 | R3: =INT((R4-1)/12)+1 | S3: =INT((S4-1)/12)+1 | T3: =INT((T4-1)/12)+1 | U3: =INT((U4-1)/12)+1 | V3: =INT((V4-1)/12)+1 | ... AX3: =INT((AX4-1)/12)+1
N4: Month # | O4: 1 | P4: 2 | Q4: 3 | R4: 4 | S4: 5 | T4: 6 | U4: 7 | V4: 8 | W4: 9 | X4: 10 | Y4: 11 | Z4: 12 | AA4: 13 | AB4: 14 | AC4: 15 | AD4: 16 | AE4: 17 | AF4: 18 | AG4: 19 | AH4: 20 | AI4: 21 | AJ4: 22 | AK4: 23 | AL4: 24 | AM4: 25 | AN4: 26 | AO4: 27 | AP4: 28 | AQ4: 29 | AR4: 30 | AS4: 31 | AT4: 32 | AU4: 33 | AV4: 34 | AW4: 35 | AX4: 36
A5: Item | B5: Category | C5: Low ($) | D5: High ($) | E5: Model ($ per period) | F5: Frequency | G5: Start month | H5: End month | I5: Year 1 total | J5: Year 2 total | K5: Year 3 total | L5: Source | M5: Status | N5: Include (1/0) | O5: =DATE(YEAR('Assumptions'!$C$8),MONTH('Assumptions'!$C$8)+O4-1,1) | P5: =DATE(YEAR('Assumptions'!$C$8),MONTH('Assumptions'!$C$8)+P4-1,1) | Q5: =DATE(YEAR('Assumptions'!$C$8),MONTH('Assumptions'!$C$8)+Q4-1,1) | R5: =DATE(YEAR('Assumptions'!$C$8),MONTH('Assumptions'!$C$8)+R4-1,1) | S5: =DATE(YEAR('Assumptions'!$C$8),MONTH('Assumptions'!$C$8)+S4-1,1) | T5: =DATE(YEAR('Assumptions'!$C$8),MONTH('Assumptions'!$C$8)+T4-1,1) | U5: =DATE(YEAR('Assumptions'!$C$8),MONTH('Assumptions'!$C$8)+U4-1,1) | V5: =DATE(YEAR('Assumptions'!$C$8),MONTH('Assumptions'!$C$8)+V4-1,1) | ... AX5: =DATE(YEAR('Assumptions'!$C$8),MONTH('Assumptions'!$C$8)+AX4-1,1)
A6: Shopify Basic plan | B6: Store | C6: 39 | D6: 39 | E6: =C6+'Assumptions'!$C$10*(D6-C6) | F6: Monthly | G6: 1 | H6: 36 | I6: =SUMIF($O$3:$AX$3,1,O6:AX6) | J6: =SUMIF($O$3:$AX$3,2,O6:AX6) | K6: =SUMIF($O$3:$AX$3,3,O6:AX6) | L6: storefront-setup-guide §1: $39/mo ($29 billed yearly). | M6: Repo [VERIFY] | N6: 1 | O6: =$N6*IF(AND(O$4>=$G6,O$4<=$H6),IF($F6="Monthly",$E6,IF(MOD(O$4-$G6,12)=0,$E6,0)),0) | P6: =$N6*IF(AND(P$4>=$G6,P$4<=$H6),IF($F6="Monthly",$E6,IF(MOD(P$4-$G6,12)=0,$E6,0)),0) | Q6: =$N6*IF(AND(Q$4>=$G6,Q$4<=$H6),IF($F6="Monthly",$E6,IF(MOD(Q$4-$G6,12)=0,$E6,0)),0) | R6: =$N6*IF(AND(R$4>=$G6,R$4<=$H6),IF($F6="Monthly",$E6,IF(MOD(R$4-$G6,12)=0,$E6,0)),0) | S6: =$N6*IF(AND(S$4>=$G6,S$4<=$H6),IF($F6="Monthly",$E6,IF(MOD(S$4-$G6,12)=0,$E6,0)),0) | T6: =$N6*IF(AND(T$4>=$G6,T$4<=$H6),IF($F6="Monthly",$E6,IF(MOD(T$4-$G6,12)=0,$E6,0)),0) | U6: =$N6*IF(AND(U$4>=$G6,U$4<=$H6),IF($F6="Monthly",$E6,IF(MOD(U$4-$G6,12)=0,$E6,0)),0) | V6: =$N6*IF(AND(V$4>=$G6,V$4<=$H6),IF($F6="Monthly",$E6,IF(MOD(V$4-$G6,12)=0,$E6,0)),0) | ... AX6: =$N6*IF(AND(AX$4>=$G6,AX$4<=$H6),IF($F6="Monthly",$E6,IF(MOD(AX$4-$G6,12)=0,$E6,0)),0)
A7: Business email on the brand domain | B7: Tools | C7: 7 | D7: 14 | E7: =C7+'Assumptions'!$C$10*(D7-C7) | F7: Monthly | G7: 1 | H7: 36 | I7: =SUMIF($O$3:$AX$3,1,O7:AX7) | J7: =SUMIF($O$3:$AX$3,2,O7:AX7) | K7: =SUMIF($O$3:$AX$3,3,O7:AX7) | L7: BLIND-SPOTS #4: about $7-$14 a month. | M7: Repo | N7: 1 | O7: =$N7*IF(AND(O$4>=$G7,O$4<=$H7),IF($F7="Monthly",$E7,IF(MOD(O$4-$G7,12)=0,$E7,0)),0) | P7: =$N7*IF(AND(P$4>=$G7,P$4<=$H7),IF($F7="Monthly",$E7,IF(MOD(P$4-$G7,12)=0,$E7,0)),0) | Q7: =$N7*IF(AND(Q$4>=$G7,Q$4<=$H7),IF($F7="Monthly",$E7,IF(MOD(Q$4-$G7,12)=0,$E7,0)),0) | R7: =$N7*IF(AND(R$4>=$G7,R$4<=$H7),IF($F7="Monthly",$E7,IF(MOD(R$4-$G7,12)=0,$E7,0)),0) | S7: =$N7*IF(AND(S$4>=$G7,S$4<=$H7),IF($F7="Monthly",$E7,IF(MOD(S$4-$G7,12)=0,$E7,0)),0) | T7: =$N7*IF(AND(T$4>=$G7,T$4<=$H7),IF($F7="Monthly",$E7,IF(MOD(T$4-$G7,12)=0,$E7,0)),0) | U7: =$N7*IF(AND(U$4>=$G7,U$4<=$H7),IF($F7="Monthly",$E7,IF(MOD(U$4-$G7,12)=0,$E7,0)),0) | V7: =$N7*IF(AND(V$4>=$G7,V$4<=$H7),IF($F7="Monthly",$E7,IF(MOD(V$4-$G7,12)=0,$E7,0)),0) | ... AX7: =$N7*IF(AND(AX$4>=$G7,AX$4<=$H7),IF($F7="Monthly",$E7,IF(MOD(AX$4-$G7,12)=0,$E7,0)),0)
A8: Password manager | B8: Tools | C8: 0 | D8: 40 | E8: =C8+'Assumptions'!$C$10*(D8-C8) | F8: Annual | G8: 1 | H8: 36 | I8: =SUMIF($O$3:$AX$3,1,O8:AX8) | J8: =SUMIF($O$3:$AX$3,2,O8:AX8) | K8: =SUMIF($O$3:$AX$3,3,O8:AX8) | L8: BLIND-SPOTS #4: $0-$40 a year. | M8: Repo | N8: 1 | O8: =$N8*IF(AND(O$4>=$G8,O$4<=$H8),IF($F8="Monthly",$E8,IF(MOD(O$4-$G8,12)=0,$E8,0)),0) | P8: =$N8*IF(AND(P$4>=$G8,P$4<=$H8),IF($F8="Monthly",$E8,IF(MOD(P$4-$G8,12)=0,$E8,0)),0) | Q8: =$N8*IF(AND(Q$4>=$G8,Q$4<=$H8),IF($F8="Monthly",$E8,IF(MOD(Q$4-$G8,12)=0,$E8,0)),0) | R8: =$N8*IF(AND(R$4>=$G8,R$4<=$H8),IF($F8="Monthly",$E8,IF(MOD(R$4-$G8,12)=0,$E8,0)),0) | S8: =$N8*IF(AND(S$4>=$G8,S$4<=$H8),IF($F8="Monthly",$E8,IF(MOD(S$4-$G8,12)=0,$E8,0)),0) | T8: =$N8*IF(AND(T$4>=$G8,T$4<=$H8),IF($F8="Monthly",$E8,IF(MOD(T$4-$G8,12)=0,$E8,0)),0) | U8: =$N8*IF(AND(U$4>=$G8,U$4<=$H8),IF($F8="Monthly",$E8,IF(MOD(U$4-$G8,12)=0,$E8,0)),0) | V8: =$N8*IF(AND(V$4>=$G8,V$4<=$H8),IF($F8="Monthly",$E8,IF(MOD(V$4-$G8,12)=0,$E8,0)),0) | ... AX8: =$N8*IF(AND(AX$4>=$G8,AX$4<=$H8),IF($F8="Monthly",$E8,IF(MOD(AX$4-$G8,12)=0,$E8,0)),0)
A9: Email platform, year 1 (free tiers, then budget) | B9: Email | C9: 0 | D9: 20 | E9: =C9+'Assumptions'!$C$10*(D9-C9) | F9: Monthly | G9: 1 | H9: 12 | I9: =SUMIF($O$3:$AX$3,1,O9:AX9) | J9: =SUMIF($O$3:$AX$3,2,O9:AX9) | K9: =SUMIF($O$3:$AX$3,3,O9:AX9) | L9: MARKETING-PLAYBOOK: Klaviyo free 250 profiles; budget $20/mo. | M9: Repo [VERIFY] | N9: 1 | O9: =$N9*IF(AND(O$4>=$G9,O$4<=$H9),IF($F9="Monthly",$E9,IF(MOD(O$4-$G9,12)=0,$E9,0)),0) | P9: =$N9*IF(AND(P$4>=$G9,P$4<=$H9),IF($F9="Monthly",$E9,IF(MOD(P$4-$G9,12)=0,$E9,0)),0) | Q9: =$N9*IF(AND(Q$4>=$G9,Q$4<=$H9),IF($F9="Monthly",$E9,IF(MOD(Q$4-$G9,12)=0,$E9,0)),0) | R9: =$N9*IF(AND(R$4>=$G9,R$4<=$H9),IF($F9="Monthly",$E9,IF(MOD(R$4-$G9,12)=0,$E9,0)),0) | S9: =$N9*IF(AND(S$4>=$G9,S$4<=$H9),IF($F9="Monthly",$E9,IF(MOD(S$4-$G9,12)=0,$E9,0)),0) | T9: =$N9*IF(AND(T$4>=$G9,T$4<=$H9),IF($F9="Monthly",$E9,IF(MOD(T$4-$G9,12)=0,$E9,0)),0) | U9: =$N9*IF(AND(U$4>=$G9,U$4<=$H9),IF($F9="Monthly",$E9,IF(MOD(U$4-$G9,12)=0,$E9,0)),0) | V9: =$N9*IF(AND(V$4>=$G9,V$4<=$H9),IF($F9="Monthly",$E9,IF(MOD(V$4-$G9,12)=0,$E9,0)),0) | ... AX9: =$N9*IF(AND(AX$4>=$G9,AX$4<=$H9),IF($F9="Monthly",$E9,IF(MOD(AX$4-$G9,12)=0,$E9,0)),0)
A10: Email platform, years 2-3 | B10: Email | C10: 20 | D10: 39 | E10: =C10+'Assumptions'!$C$10*(D10-C10) | F10: Monthly | G10: 13 | H10: 36 | I10: =SUMIF($O$3:$AX$3,1,O10:AX10) | J10: =SUMIF($O$3:$AX$3,2,O10:AX10) | K10: =SUMIF($O$3:$AX$3,3,O10:AX10) | L10: MARKETING-PLAYBOOK: about $20-39/mo later. | M10: Repo [VERIFY] | N10: 1 | O10: =$N10*IF(AND(O$4>=$G10,O$4<=$H10),IF($F10="Monthly",$E10,IF(MOD(O$4-$G10,12)=0,$E10,0)),0) | P10: =$N10*IF(AND(P$4>=$G10,P$4<=$H10),IF($F10="Monthly",$E10,IF(MOD(P$4-$G10,12)=0,$E10,0)),0) | Q10: =$N10*IF(AND(Q$4>=$G10,Q$4<=$H10),IF($F10="Monthly",$E10,IF(MOD(Q$4-$G10,12)=0,$E10,0)),0) | R10: =$N10*IF(AND(R$4>=$G10,R$4<=$H10),IF($F10="Monthly",$E10,IF(MOD(R$4-$G10,12)=0,$E10,0)),0) | S10: =$N10*IF(AND(S$4>=$G10,S$4<=$H10),IF($F10="Monthly",$E10,IF(MOD(S$4-$G10,12)=0,$E10,0)),0) | T10: =$N10*IF(AND(T$4>=$G10,T$4<=$H10),IF($F10="Monthly",$E10,IF(MOD(T$4-$G10,12)=0,$E10,0)),0) | U10: =$N10*IF(AND(U$4>=$G10,U$4<=$H10),IF($F10="Monthly",$E10,IF(MOD(U$4-$G10,12)=0,$E10,0)),0) | V10: =$N10*IF(AND(V$4>=$G10,V$4<=$H10),IF($F10="Monthly",$E10,IF(MOD(V$4-$G10,12)=0,$E10,0)),0) | ... AX10: =$N10*IF(AND(AX$4>=$G10,AX$4<=$H10),IF($F10="Monthly",$E10,IF(MOD(AX$4-$G10,12)=0,$E10,0)),0)
A11: Claude plan that runs the scheduled routines | B11: Automation | C11: 100 | D11: 200 | E11: =C11+'Assumptions'!$C$10*(D11-C11) | F11: Monthly | G11: 1 | H11: 36 | I11: =SUMIF($O$3:$AX$3,1,O11:AX11) | J11: =SUMIF($O$3:$AX$3,2,O11:AX11) | K11: =SUMIF($O$3:$AX$3,3,O11:AX11) | L11: No price in the repo; a higher-usage tier is assumed because routines run weekly (ops/ROUTINE.md). | M11: Assumption [VERIFY] | N11: 1 | O11: =$N11*IF(AND(O$4>=$G11,O$4<=$H11),IF($F11="Monthly",$E11,IF(MOD(O$4-$G11,12)=0,$E11,0)),0) | P11: =$N11*IF(AND(P$4>=$G11,P$4<=$H11),IF($F11="Monthly",$E11,IF(MOD(P$4-$G11,12)=0,$E11,0)),0) | Q11: =$N11*IF(AND(Q$4>=$G11,Q$4<=$H11),IF($F11="Monthly",$E11,IF(MOD(Q$4-$G11,12)=0,$E11,0)),0) | R11: =$N11*IF(AND(R$4>=$G11,R$4<=$H11),IF($F11="Monthly",$E11,IF(MOD(R$4-$G11,12)=0,$E11,0)),0) | S11: =$N11*IF(AND(S$4>=$G11,S$4<=$H11),IF($F11="Monthly",$E11,IF(MOD(S$4-$G11,12)=0,$E11,0)),0) | T11: =$N11*IF(AND(T$4>=$G11,T$4<=$H11),IF($F11="Monthly",$E11,IF(MOD(T$4-$G11,12)=0,$E11,0)),0) | U11: =$N11*IF(AND(U$4>=$G11,U$4<=$H11),IF($F11="Monthly",$E11,IF(MOD(U$4-$G11,12)=0,$E11,0)),0) | V11: =$N11*IF(AND(V$4>=$G11,V$4<=$H11),IF($F11="Monthly",$E11,IF(MOD(V$4-$G11,12)=0,$E11,0)),0) | ... AX11: =$N11*IF(AND(AX$4>=$G11,AX$4<=$H11),IF($F11="Monthly",$E11,IF(MOD(AX$4-$G11,12)=0,$E11,0)),0)
A12: Claude usage-credit cap (hard limit) | B12: Automation | C12: 0 | D12: 25 | E12: =C12+'Assumptions'!$C$10*(D12-C12) | F12: Monthly | G12: 1 | H12: 36 | I12: =SUMIF($O$3:$AX$3,1,O12:AX12) | J12: =SUMIF($O$3:$AX$3,2,O12:AX12) | K12: =SUMIF($O$3:$AX$3,3,O12:AX12) | L12: ops/GAPS-ROUND-2.md G2-06: fixed monthly limit such as $25. | M12: Repo | N12: 1 | O12: =$N12*IF(AND(O$4>=$G12,O$4<=$H12),IF($F12="Monthly",$E12,IF(MOD(O$4-$G12,12)=0,$E12,0)),0) | P12: =$N12*IF(AND(P$4>=$G12,P$4<=$H12),IF($F12="Monthly",$E12,IF(MOD(P$4-$G12,12)=0,$E12,0)),0) | Q12: =$N12*IF(AND(Q$4>=$G12,Q$4<=$H12),IF($F12="Monthly",$E12,IF(MOD(Q$4-$G12,12)=0,$E12,0)),0) | R12: =$N12*IF(AND(R$4>=$G12,R$4<=$H12),IF($F12="Monthly",$E12,IF(MOD(R$4-$G12,12)=0,$E12,0)),0) | S12: =$N12*IF(AND(S$4>=$G12,S$4<=$H12),IF($F12="Monthly",$E12,IF(MOD(S$4-$G12,12)=0,$E12,0)),0) | T12: =$N12*IF(AND(T$4>=$G12,T$4<=$H12),IF($F12="Monthly",$E12,IF(MOD(T$4-$G12,12)=0,$E12,0)),0) | U12: =$N12*IF(AND(U$4>=$G12,U$4<=$H12),IF($F12="Monthly",$E12,IF(MOD(U$4-$G12,12)=0,$E12,0)),0) | V12: =$N12*IF(AND(V$4>=$G12,V$4<=$H12),IF($F12="Monthly",$E12,IF(MOD(V$4-$G12,12)=0,$E12,0)),0) | ... AX12: =$N12*IF(AND(AX$4>=$G12,AX$4<=$H12),IF($F12="Monthly",$E12,IF(MOD(AX$4-$G12,12)=0,$E12,0)),0)
A13: QuickBooks Online (Simple Start to Essentials) | B13: Bookkeeping | C13: 38 | D13: 85 | E13: =C13+'Assumptions'!$C$10*(D13-C13) | F13: Monthly | G13: 1 | H13: 36 | I13: =SUMIF($O$3:$AX$3,1,O13:AX13) | J13: =SUMIF($O$3:$AX$3,2,O13:AX13) | K13: =SUMIF($O$3:$AX$3,3,O13:AX13) | L13: finance/money-and-tax-setup.md: $38 Simple Start; Essentials $75-$85 (UNVERIFIED). | M13: Repo [VERIFY] | N13: 1 | O13: =$N13*IF(AND(O$4>=$G13,O$4<=$H13),IF($F13="Monthly",$E13,IF(MOD(O$4-$G13,12)=0,$E13,0)),0) | P13: =$N13*IF(AND(P$4>=$G13,P$4<=$H13),IF($F13="Monthly",$E13,IF(MOD(P$4-$G13,12)=0,$E13,0)),0) | Q13: =$N13*IF(AND(Q$4>=$G13,Q$4<=$H13),IF($F13="Monthly",$E13,IF(MOD(Q$4-$G13,12)=0,$E13,0)),0) | R13: =$N13*IF(AND(R$4>=$G13,R$4<=$H13),IF($F13="Monthly",$E13,IF(MOD(R$4-$G13,12)=0,$E13,0)),0) | S13: =$N13*IF(AND(S$4>=$G13,S$4<=$H13),IF($F13="Monthly",$E13,IF(MOD(S$4-$G13,12)=0,$E13,0)),0) | T13: =$N13*IF(AND(T$4>=$G13,T$4<=$H13),IF($F13="Monthly",$E13,IF(MOD(T$4-$G13,12)=0,$E13,0)),0) | U13: =$N13*IF(AND(U$4>=$G13,U$4<=$H13),IF($F13="Monthly",$E13,IF(MOD(U$4-$G13,12)=0,$E13,0)),0) | V13: =$N13*IF(AND(V$4>=$G13,V$4<=$H13),IF($F13="Monthly",$E13,IF(MOD(V$4-$G13,12)=0,$E13,0)),0) | ... AX13: =$N13*IF(AND(AX$4>=$G13,AX$4<=$H13),IF($F13="Monthly",$E13,IF(MOD(AX$4-$G13,12)=0,$E13,0)),0)
A14: Link My Books settlement connector (1-3 channels) | B14: Connectors | C14: 21 | D14: 47 | E14: =C14+'Assumptions'!$C$10*(D14-C14) | F14: Monthly | G14: 3 | H14: 36 | I14: =SUMIF($O$3:$AX$3,1,O14:AX14) | J14: =SUMIF($O$3:$AX$3,2,O14:AX14) | K14: =SUMIF($O$3:$AX$3,3,O14:AX14) | L14: money-and-tax-setup: from $21/mo, about $13 per extra channel. | M14: Repo [VERIFY] | N14: 1 | O14: =$N14*IF(AND(O$4>=$G14,O$4<=$H14),IF($F14="Monthly",$E14,IF(MOD(O$4-$G14,12)=0,$E14,0)),0) | P14: =$N14*IF(AND(P$4>=$G14,P$4<=$H14),IF($F14="Monthly",$E14,IF(MOD(P$4-$G14,12)=0,$E14,0)),0) | Q14: =$N14*IF(AND(Q$4>=$G14,Q$4<=$H14),IF($F14="Monthly",$E14,IF(MOD(Q$4-$G14,12)=0,$E14,0)),0) | R14: =$N14*IF(AND(R$4>=$G14,R$4<=$H14),IF($F14="Monthly",$E14,IF(MOD(R$4-$G14,12)=0,$E14,0)),0) | S14: =$N14*IF(AND(S$4>=$G14,S$4<=$H14),IF($F14="Monthly",$E14,IF(MOD(S$4-$G14,12)=0,$E14,0)),0) | T14: =$N14*IF(AND(T$4>=$G14,T$4<=$H14),IF($F14="Monthly",$E14,IF(MOD(T$4-$G14,12)=0,$E14,0)),0) | U14: =$N14*IF(AND(U$4>=$G14,U$4<=$H14),IF($F14="Monthly",$E14,IF(MOD(U$4-$G14,12)=0,$E14,0)),0) | V14: =$N14*IF(AND(V$4>=$G14,V$4<=$H14),IF($F14="Monthly",$E14,IF(MOD(V$4-$G14,12)=0,$E14,0)),0) | ... AX14: =$N14*IF(AND(AX$4>=$G14,AX$4<=$H14),IF($F14="Monthly",$E14,IF(MOD(AX$4-$G14,12)=0,$E14,0)),0)
A15: Buyer-specific PDF stamping | B15: Tools | C15: 0 | D15: 20 | E15: =C15+'Assumptions'!$C$10*(D15-C15) | F15: Monthly | G15: 3 | H15: 36 | I15: =SUMIF($O$3:$AX$3,1,O15:AX15) | J15: =SUMIF($O$3:$AX$3,2,O15:AX15) | K15: =SUMIF($O$3:$AX$3,3,O15:AX15) | L15: PROTECTION-PLAN: about $0-$20/mo. | M15: Repo [VERIFY] | N15: 1 | O15: =$N15*IF(AND(O$4>=$G15,O$4<=$H15),IF($F15="Monthly",$E15,IF(MOD(O$4-$G15,12)=0,$E15,0)),0) | P15: =$N15*IF(AND(P$4>=$G15,P$4<=$H15),IF($F15="Monthly",$E15,IF(MOD(P$4-$G15,12)=0,$E15,0)),0) | Q15: =$N15*IF(AND(Q$4>=$G15,Q$4<=$H15),IF($F15="Monthly",$E15,IF(MOD(Q$4-$G15,12)=0,$E15,0)),0) | R15: =$N15*IF(AND(R$4>=$G15,R$4<=$H15),IF($F15="Monthly",$E15,IF(MOD(R$4-$G15,12)=0,$E15,0)),0) | S15: =$N15*IF(AND(S$4>=$G15,S$4<=$H15),IF($F15="Monthly",$E15,IF(MOD(S$4-$G15,12)=0,$E15,0)),0) | T15: =$N15*IF(AND(T$4>=$G15,T$4<=$H15),IF($F15="Monthly",$E15,IF(MOD(T$4-$G15,12)=0,$E15,0)),0) | U15: =$N15*IF(AND(U$4>=$G15,U$4<=$H15),IF($F15="Monthly",$E15,IF(MOD(U$4-$G15,12)=0,$E15,0)),0) | V15: =$N15*IF(AND(V$4>=$G15,V$4<=$H15),IF($F15="Monthly",$E15,IF(MOD(V$4-$G15,12)=0,$E15,0)),0) | ... AX15: =$N15*IF(AND(AX$4>=$G15,AX$4<=$H15),IF($F15="Monthly",$E15,IF(MOD(AX$4-$G15,12)=0,$E15,0)),0)
A16: Social scheduler | B16: Tools | C16: 0 | D16: 30 | E16: =C16+'Assumptions'!$C$10*(D16-C16) | F16: Monthly | G16: 3 | H16: 36 | I16: =SUMIF($O$3:$AX$3,1,O16:AX16) | J16: =SUMIF($O$3:$AX$3,2,O16:AX16) | K16: =SUMIF($O$3:$AX$3,3,O16:AX16) | L16: Publisher role posts through a scheduler (section 5.3); no price in the repo. | M16: Assumption [VERIFY] | N16: 1 | O16: =$N16*IF(AND(O$4>=$G16,O$4<=$H16),IF($F16="Monthly",$E16,IF(MOD(O$4-$G16,12)=0,$E16,0)),0) | P16: =$N16*IF(AND(P$4>=$G16,P$4<=$H16),IF($F16="Monthly",$E16,IF(MOD(P$4-$G16,12)=0,$E16,0)),0) | Q16: =$N16*IF(AND(Q$4>=$G16,Q$4<=$H16),IF($F16="Monthly",$E16,IF(MOD(Q$4-$G16,12)=0,$E16,0)),0) | R16: =$N16*IF(AND(R$4>=$G16,R$4<=$H16),IF($F16="Monthly",$E16,IF(MOD(R$4-$G16,12)=0,$E16,0)),0) | S16: =$N16*IF(AND(S$4>=$G16,S$4<=$H16),IF($F16="Monthly",$E16,IF(MOD(S$4-$G16,12)=0,$E16,0)),0) | T16: =$N16*IF(AND(T$4>=$G16,T$4<=$H16),IF($F16="Monthly",$E16,IF(MOD(T$4-$G16,12)=0,$E16,0)),0) | U16: =$N16*IF(AND(U$4>=$G16,U$4<=$H16),IF($F16="Monthly",$E16,IF(MOD(U$4-$G16,12)=0,$E16,0)),0) | V16: =$N16*IF(AND(V$4>=$G16,V$4<=$H16),IF($F16="Monthly",$E16,IF(MOD(V$4-$G16,12)=0,$E16,0)),0) | ... AX16: =$N16*IF(AND(AX$4>=$G16,AX$4<=$H16),IF($F16="Monthly",$E16,IF(MOD(AX$4-$G16,12)=0,$E16,0)),0)
A17: Own-site review app | B17: Tools | C17: 0 | D17: 15 | E17: =C17+'Assumptions'!$C$10*(D17-C17) | F17: Monthly | G17: 3 | H17: 36 | I17: =SUMIF($O$3:$AX$3,1,O17:AX17) | J17: =SUMIF($O$3:$AX$3,2,O17:AX17) | K17: =SUMIF($O$3:$AX$3,3,O17:AX17) | L17: Section 4.7 own-site review app; no price in the repo. | M17: Assumption [VERIFY] | N17: 1 | O17: =$N17*IF(AND(O$4>=$G17,O$4<=$H17),IF($F17="Monthly",$E17,IF(MOD(O$4-$G17,12)=0,$E17,0)),0) | P17: =$N17*IF(AND(P$4>=$G17,P$4<=$H17),IF($F17="Monthly",$E17,IF(MOD(P$4-$G17,12)=0,$E17,0)),0) | Q17: =$N17*IF(AND(Q$4>=$G17,Q$4<=$H17),IF($F17="Monthly",$E17,IF(MOD(Q$4-$G17,12)=0,$E17,0)),0) | R17: =$N17*IF(AND(R$4>=$G17,R$4<=$H17),IF($F17="Monthly",$E17,IF(MOD(R$4-$G17,12)=0,$E17,0)),0) | S17: =$N17*IF(AND(S$4>=$G17,S$4<=$H17),IF($F17="Monthly",$E17,IF(MOD(S$4-$G17,12)=0,$E17,0)),0) | T17: =$N17*IF(AND(T$4>=$G17,T$4<=$H17),IF($F17="Monthly",$E17,IF(MOD(T$4-$G17,12)=0,$E17,0)),0) | U17: =$N17*IF(AND(U$4>=$G17,U$4<=$H17),IF($F17="Monthly",$E17,IF(MOD(U$4-$G17,12)=0,$E17,0)),0) | V17: =$N17*IF(AND(V$4>=$G17,V$4<=$H17),IF($F17="Monthly",$E17,IF(MOD(V$4-$G17,12)=0,$E17,0)),0) | ... AX17: =$N17*IF(AND(AX$4>=$G17,AX$4<=$H17),IF($F17="Monthly",$E17,IF(MOD(AX$4-$G17,12)=0,$E17,0)),0)
... A34: Upload assistant for KDP/IngramSpark/TpT packets (switch: when uploads exceed the founder cap) | B34: Contractor | C34: 0 | D34: 200 | E34: =C34+'Assumptions'!$C$10*(D34-C34) | F34: Monthly | G34: 7 | H34: 36 | I34: =SUMIF($O$3:$AX$3,1,O34:AX34) | J34: =SUMIF($O$3:$AX$3,2,O34:AX34) | K34: =SUMIF($O$3:$AX$3,3,O34:AX34) | L34: Section 5.2; not priced in the repo. | M34: Assumption | N34: 0 | O34: =$N34*IF(AND(O$4>=$G34,O$4<=$H34),IF($F34="Monthly",$E34,IF(MOD(O$4-$G34,12)=0,$E34,0)),0) | P34: =$N34*IF(AND(P$4>=$G34,P$4<=$H34),IF($F34="Monthly",$E34,IF(MOD(P$4-$G34,12)=0,$E34,0)),0) | Q34: =$N34*IF(AND(Q$4>=$G34,Q$4<=$H34),IF($F34="Monthly",$E34,IF(MOD(Q$4-$G34,12)=0,$E34,0)),0) | R34: =$N34*IF(AND(R$4>=$G34,R$4<=$H34),IF($F34="Monthly",$E34,IF(MOD(R$4-$G34,12)=0,$E34,0)),0) | S34: =$N34*IF(AND(S$4>=$G34,S$4<=$H34),IF($F34="Monthly",$E34,IF(MOD(S$4-$G34,12)=0,$E34,0)),0) | T34: =$N34*IF(AND(T$4>=$G34,T$4<=$H34),IF($F34="Monthly",$E34,IF(MOD(T$4-$G34,12)=0,$E34,0)),0) | U34: =$N34*IF(AND(U$4>=$G34,U$4<=$H34),IF($F34="Monthly",$E34,IF(MOD(U$4-$G34,12)=0,$E34,0)),0) | V34: =$N34*IF(AND(V$4>=$G34,V$4<=$H34),IF($F34="Monthly",$E34,IF(MOD(V$4-$G34,12)=0,$E34,0)),0) | ... AX34: =$N34*IF(AND(AX$4>=$G34,AX$4<=$H34),IF($F34="Monthly",$E34,IF(MOD(AX$4-$G34,12)=0,$E34,0)),0)
A35: Subtotal | I35: =SUM(I6:I34) | J35: =SUM(J6:J34) | K35: =SUM(K6:K34) | O35: =SUM(O6:O34) | P35: =SUM(P6:P34) | Q35: =SUM(Q6:Q34) | R35: =SUM(R6:R34) | S35: =SUM(S6:S34) | T35: =SUM(T6:T34) | U35: =SUM(U6:U34) | V35: =SUM(V6:V34) | ... AX35: =SUM(AX6:AX34)
A36: Operating contingency | I36: =I35*'Assumptions'!$C$20 | J36: =J35*'Assumptions'!$C$20 | K36: =K35*'Assumptions'!$C$20 | O36: =O35*'Assumptions'!$C$20 | P36: =P35*'Assumptions'!$C$20 | Q36: =Q35*'Assumptions'!$C$20 | R36: =R35*'Assumptions'!$C$20 | S36: =S35*'Assumptions'!$C$20 | T36: =T35*'Assumptions'!$C$20 | U36: =U35*'Assumptions'!$C$20 | V36: =V35*'Assumptions'!$C$20 | ... AX36: =AX35*'Assumptions'!$C$20
A37: Total monthly operating costs | I37: =I35+I36 | J37: =J35+J36 | K37: =K35+K36 | O37: =O35+O36 | P37: =P35+P36 | Q37: =Q35+Q36 | R37: =R35+R36 | S37: =S35+S36 | T37: =T35+T36 | U37: =U35+U36 | V37: =V35+V36 | ... AX37: =AX35+AX36
A39: Wave-specific fixed costs (3PL minimum, Seller Central, retail EDI and insurance uplift) are added in the forecast only when that wave is live.

Sheet 36-Month Forecast
A1: 36-month forecast: three scenarios, driven by traffic -> conversion -> orders -> order value, by channel and wave
A2: Traffic = trend (launch traffic compounded by monthly growth) x seasonality. Conversion ramps up over the review-ramp months. Net contribution = items x blended net per item from Unit Economics. Figures are planning estimates, not promises of income.
A4: Model month # | B4: Unit / note | C4: 1 | D4: 2 | E4: 3 | F4: 4 | G4: 5 | H4: 6 | I4: 7 | J4: 8 | K4: 9 | L4: 10 | M4: 11 | N4: 12 | O4: 13 | P4: 14 | Q4: 15 | R4: 16 | S4: 17 | T4: 18 | U4: 19 | V4: 20 | W4: 21 | X4: 22 | Y4: 23 | Z4: 24 | AA4: 25 | AB4: 26 | AC4: 27 | AD4: 28 | AE4: 29 | AF4: 30 | AG4: 31 | AH4: 32 | AI4: 33 | AJ4: 34 | AK4: 35 | AL4: 36 | AM4: Oct-Sep | AN4: Oct-Sep | AO4: Oct-Sep | AP4: Total
A5: Month | C5: =DATE(YEAR('Assumptions'!$C$8),MONTH('Assumptions'!$C$8)+C4-1,1) | D5: =DATE(YEAR('Assumptions'!$C$8),MONTH('Assumptions'!$C$8)+D4-1,1) | E5: =DATE(YEAR('Assumptions'!$C$8),MONTH('Assumptions'!$C$8)+E4-1,1) | F5: =DATE(YEAR('Assumptions'!$C$8),MONTH('Assumptions'!$C$8)+F4-1,1) | G5: =DATE(YEAR('Assumptions'!$C$8),MONTH('Assumptions'!$C$8)+G4-1,1) | H5: =DATE(YEAR('Assumptions'!$C$8),MONTH('Assumptions'!$C$8)+H4-1,1) | I5: =DATE(YEAR('Assumptions'!$C$8),MONTH('Assumptions'!$C$8)+I4-1,1) | J5: =DATE(YEAR('Assumptions'!$C$8),MONTH('Assumptions'!$C$8)+J4-1,1) | ... AL5: =DATE(YEAR('Assumptions'!$C$8),MONTH('Assumptions'!$C$8)+AL4-1,1) | AM5: Year 1 | AN5: Year 2 | AO5: Year 3 | AP5: 36 months
A6: Model year | C6: =INT((C4-1)/12)+1 | D6: =INT((D4-1)/12)+1 | E6: =INT((E4-1)/12)+1 | F6: =INT((F4-1)/12)+1 | G6: =INT((G4-1)/12)+1 | H6: =INT((H4-1)/12)+1 | I6: =INT((I4-1)/12)+1 | J6: =INT((J4-1)/12)+1 | ... AL6: =INT((AL4-1)/12)+1
