Workbook

Sheet README
A1: Play Before Pixels - Bookkeeping Workbook, tax year 2026
A2: AlphaPlay LLC d/b/a Play Before Pixels | built September 27, 2026 | companion guide: /home/user/playbeforepixels/finance/money-and-tax-setup.md
A5: What this workbook is for
A6: QuickBooks Online (or Xero, if your accountant prefers it) is the official set of books. This workbook is your working log and your accountant's cross-check. Use it to:
A7: 1. Log the channels no connector covers: KDP, IngramSpark, Teachers Pay Teachers, Faire, the merchant of record, affiliates, direct invoices and events. Until QBO and Link My Books are live, log every channel here.
A8: 2. Tick every payout against a deposit in business checking (Payouts Reconciliation).
A9: 3. Work out the Maryland sales-tax return numbers (Sales Tax) and the quarterly estimate placeholders (Quarterly Estimates).
A10: 4. Keep the mileage log and the accountant checklist in one place.
A12: The monthly routine (about 30 minutes, first week of each month)
A13: 1. Download each platform's monthly statement and save it to the accountant folder (sub-folder YYYY-MM).
A14: 2. Sales Log: one row per channel per month for marketplaces and royalties; one row per order for direct sales.
A15: 3. Expenses: one row per receipt not already in QBO; pick the category from the drop-down.
... A39: Tabs
A40: Chart of Accounts | B40: The accounts to set up in QBO/Xero, the drop-down lists, and the Channel map showing how every shop's money reaches the books.
A41: Sales Log | B41: Sales by channel. Net payout is a formula.
A42: Expenses | B42: Costs, with category drop-down from the Chart of Accounts and a 1099-NEC watch column.
A43: Payouts Reconciliation | B43: Each platform payout matched to a bank deposit.
A44: Channel Summary | B44: Gross, fees, net and payouts by channel and month (formulas only). Tax year input in B3.
A45: Sales Tax | B45: Maryland taxable sales and tax you collected, with marketplace-collected sales excluded. Monthly, quarterly and annual.
A46: Quarterly Estimates | B46: Profit by IRS estimate period, SE-tax placeholder, set-aside, due dates and payment records.
A47: Mileage & Event Log | B47: Business trips and events. (The requested name 'Mileage/Event log' uses '/', which Excel does not allow in tab names.)
A48: Accountant Packet | B48: Monthly, quarterly and year-end checklist with a Status drop-down.
A50: Verification status - read this
A51: No fee, rate, threshold or deadline in this workbook was confirmed against a primary source on September 27, 2026: irs.gov, marylandtaxes.gov and the platform sites were unreachable from the research environment. Items are marked UNVERIFIED. Weekdays of due dates were computed. Your accountant confirms or replaces every rate in a yellow cell.
A53: Next year
A54: Save a copy as PlayBeforePixels_Bookkeeping_2027.xlsx, change the tax year on Channel Summary B3, type the 2027 due dates on Quarterly Estimates, clear the 2026 rows, and reset the Accountant Packet statuses.

Sheet Chart of Accounts
A1: Chart of Accounts - AlphaPlay LLC d/b/a Play Before Pixels
A2: Set these accounts up in QuickBooks Online (or Xero) with these numbers and names. The tax-line column is a suggestion only (UNVERIFIED): your accountant sets the final mapping. The drop-down lists used on the other tabs live in columns H-I, and the channel map below the chart feeds every Channel drop-down.
A4: Account # | B4: Account name | C4: Type | D4: Tax-line suggestion (UNVERIFIED) | E4: What goes here | F4: How it gets posted | H4: Expense categories (drop-down source) | I4: Income accounts (drop-down source)
A5: 1000 | B5: Business checking (AlphaPlay LLC d/b/a Play Before Pixels) | C5: Bank | D5: Balance sheet | E5: The hub. Every shop, royalty and invoice payout lands here. Pays the card, the tax reserve and taxes. | F5: Bank feed | H5: 1200 Inventory - author copies & stock | I5: 4000 Book royalties - KDP
A6: 1010 | B6: Tax reserve savings | C6: Bank | D6: Balance sheet | E6: Set-aside % of each payout (accountant sets it) plus 100% of Maryland sales tax you collect. | F6: Bank feed (record as transfers) | H6: 5000 COGS - books & stock sold | I6: 4010 Book compensation - IngramSpark
A7: 1020 | B7: PayPal Business | C7: Bank (clearing) | D7: Balance sheet | E7: PayPal sales and platform payouts sitting in PayPal before you transfer them to checking. | F7: PayPal connection or Synder (method UNVERIFIED) | H7: 5100 COGS - POD fulfillment (Printful) | I7: 4100 Sales - digital downloads (printables)
A8: 1030 | B8: Stripe clearing | C8: Clearing | D8: Balance sheet | E8: Stripe gross sales less Stripe fees until the payout reaches checking. | F8: Monthly entry from Stripe Payout Reconciliation report | H8: 5200 Shipping & postage (outbound orders) | I8: 4150 Sales - teacher resource pack
A9: 1040 | B9: Marketplace clearing (connector) | C9: Clearing | D9: Balance sheet | E9: Settlements posted by Link My Books (Etsy, TikTok Shop, Shopify) until the deposit clears. | F9: Link My Books | H9: 5300 COGS - card deck & print runs | I9: 4200 Sales - books sold direct
A10: 1100 | B10: KDP receivable | C10: Receivable | D10: Balance sheet | E10: KDP royalties earned but not yet paid (paid about 60 days after month end, UNVERIFIED). | F10: Monthly journal entry from KDP royalty report | H10: 5400 Packaging & order supplies | I10: 4250 Sales - card deck
A11: 1110 | B11: IngramSpark receivable | C11: Receivable | D11: Balance sheet | E11: IngramSpark compensation earned but not yet paid (about 90 days, UNVERIFIED). | F11: Monthly journal entry from compensation report | H11: 6000 Marketplace & platform fees | I11: 4300 Sales - POD merch
A12: 1120 | B12: Other platform receivables | C12: Receivable | D12: Balance sheet | E12: TpT, Faire, merchant-of-record and affiliate earnings not yet paid. | F12: Monthly journal entry or bank-feed coding | H12: 6050 Payment processing fees | I12: 4400 Sales - online course
A13: 1130 | B13: Accounts receivable - invoices | C13: Receivable | D13: Balance sheet | E13: Unpaid coaching, workshop and B2B/school invoices. | F13: QBO/Xero invoices | H13: 6100 Advertising & marketing | I13: 4500 Coaching (services)
A14: 1200 | B14: Inventory - author copies & stock | C14: Inventory | D14: Balance sheet; becomes COGS when sold | E14: Author copies (KDP, IngramSpark), card-deck stock and event stock. NOT an expense when bought. | F14: Card feed; accountant moves sold units to 5000 | H14: 6200 Software & subscriptions | I14: 4510 Workshops - live delivery
A15: 2000 | B15: Business credit card | C15: Credit card | D15: Balance sheet | E15: Every business charge. Paid in full from 1000 only. | F15: Card feed | H15: 6300 Publishing costs (ISBNs, proofs, revisions) | I15: 4520 Workshop kits - licenses
... A20: 3110 | B20: Owner draw - federal estimated tax | C20: Equity | D20: Not a business expense (disregarded LLC) | E20: Form 1040-ES payments made from the tax reserve. | F20: Bank feed | H20: 6700 Bank & card fees | I20: 4950 Interest income
A21: 3120 | B21: Owner draw - Maryland estimated tax | C21: Equity | D21: Not a business expense (UNVERIFIED; accountant confirms) | E21: Maryland individual estimated payments (Form PV / 502D). | F21: Bank feed | H21: 6800 Research books & education
A22: 3900 | B22: Owner equity / retained earnings | C22: Equity | D22: Balance sheet | E22: Year-end roll-forward (automatic in QBO/Xero). | F22: Automatic | H22: 6850 Workshop & event costs
A23: 4000 | B23: Book royalties - KDP | C23: Income | D23: Sch C line 1 gross receipts (UNVERIFIED; accountant confirms) | E23: KDP royalties (print cost is already netted out by Amazon). | F23: Monthly journal entry: Dr 1100 / Cr 4000 | H23: 6900 Vehicle - mileage, parking & tolls
A24: 4010 | B24: Book compensation - IngramSpark | C24: Income | D24: Sch C line 1 (UNVERIFIED) | E24: IngramSpark publisher compensation. | F24: Monthly journal entry: Dr 1110 / Cr 4010 | H24: 6950 Travel (lodging, fares)
A25: 4100 | B25: Sales - digital downloads (printables) | C25: Income | D25: Sch C line 1 (UNVERIFIED) | E25: Printables sold on Etsy, TpT, the website or a merchant of record. | F25: Connector or monthly entry | H25: 6960 Business meals
A26: 4150 | B26: Sales - teacher resource pack | C26: Income | D26: Sch C line 1 (UNVERIFIED) | E26: Teacher resource pack (mostly TpT). | F26: Monthly entry from TpT report | H26: 7000 Ask My Accountant
A27: 4200 | B27: Sales - books sold direct | C27: Income | D27: Sch C line 1 (UNVERIFIED) | E27: Signed books and author copies you sell yourself (website, events, Etsy, TikTok). | F27: Connector, Stripe or invoice
A28: 4250 | B28: Sales - card deck | C28: Income | D28: Sch C line 1 (UNVERIFIED) | E28: The card deck on any channel. | F28: Connector, Stripe or invoice
A29: 4300 | B29: Sales - POD merch | C29: Income | D29: Sch C line 1 (UNVERIFIED) | E29: Tees, totes, mugs, stickers, onesies (fulfilled by Printful). | F29: Connector
A30: 4400 | B30: Sales - online course | C30: Income | D30: Sch C line 1 (UNVERIFIED) | E30: Course sales (merchant of record, or Stripe for US buyers). | F30: Monthly entry from payout report
A31: 4500 | B31: Coaching (services) | C31: Income | D31: Sch C line 1 (UNVERIFIED) | E31: Parent coaching (audio or written). | F31: Stripe / invoice
A32: 4510 | B32: Workshops - live delivery | C32: Income | D32: Sch C line 1 (UNVERIFIED) | E32: Workshops you deliver (audio or in person). | F32: Stripe / invoice
A33: 4520 | B33: Workshop kits - licenses | C33: Income | D33: Sch C line 1 (UNVERIFIED) | E33: Host-it-yourself kits sold as downloads (possibly taxable digital product in MD, UNVERIFIED). | F33: Stripe, merchant of record or invoice
A34: 4600 | B34: Wholesale & group/B2B sales | C34: Income | D34: Sch C line 1 (UNVERIFIED) | E34: Faire wholesale, school/PTA/group orders. | F34: Monthly entry (Faire) or invoice
A35: 4700 | B35: Affiliate income | C35: Income | D35: Sch C line 1 or other income (accountant decides) | E35: Amazon Associates and Bookshop.org commissions. | F35: Code the deposit in the bank feed
A36: 4800 | B36: Shipping charged to customers | C36: Income | D36: Sch C line 1 (UNVERIFIED) | E36: Shipping buyers paid you. | F36: Connector or entry
A37: 4900 | B37: Refunds & returns | C37: Contra-income | D37: Sch C line 2 returns & allowances (UNVERIFIED) | E37: Refunds you gave (connector splits these out). | F37: Connector or entry
A38: 4950 | B38: Interest income | C38: Other income | D38: Usually not Sch C (accountant decides) | E38: Bank interest (1099-INT if $10 or more, UNVERIFIED). | F38: Bank feed
... A60: 7000 | B60: Ask My Accountant | C60: Suspense | D60: Must be empty at year end | E60: Anything you are unsure of. Add a note. Clear before year end. | F60: Any
A63: Channel map - how every shop's money reaches the books
A64: Column A feeds every Channel drop-down in this workbook. Timing, fees and tax forms are UNVERIFIED (no primary source was reachable on Sept 27, 2026). Check the source URL on the day you sign up.
A65: Channel | B65: What sells there | C65: Who collects sales tax | D65: Payout rail & timing (UNVERIFIED) | E65: Income account(s) | F65: Fee account | G65: How it reaches QBO/Xero | H65: Monthly report to save | I65: Tax form you may receive (UNVERIFIED) | J65: Check at (source)
A66: Amazon KDP | B66: Paperback & hardcover picture books, ebooks (board books are NOT a KDP format, UNVERIFIED) | C66: Amazon is the seller; not on your MD return (UNVERIFIED) | D66: EFT to 1000, ~60 days after month end, per marketplace | E66: 4000 | F66: None (print cost netted in royalty) | G66: Monthly journal entry Dr 1100 / Cr 4000; clear on deposit | H66: Royalty + Payments reports | I66: 1099-MISC (royalty threshold $10) | J66: https://kdp.amazon.com/en_US/help/topic/G200641050
A67: IngramSpark | B67: Hardcover & paperback for bookstores, libraries, schools | C67: The retailer (your print orders are costs) | D67: To 1000, ~90 days after month end | E67: 4010 | F67: Your print orders -> 1200 via card | G67: Monthly journal entry Dr 1110 / Cr 4010 | H67: Compensation report | I67: 1099-MISC possible | J67: https://www.ingramspark.com/
A68: Etsy | B68: Printables, card deck, Printful merch, signed books | C68: Etsy (marketplace facilitator; also EU/UK VAT on downloads) | D68: Etsy Payments deposit to 1000: daily/weekly/biweekly/monthly (you choose) | E68: 4100 / 4250 / 4300 / 4200 + 4800 | F68: 6000-Etsy | G68: Link My Books -> QBO | H68: Monthly CSV statement | I68: 1099-K (federal >$20,000 and >200; MD reported $600) | J68: https://www.etsy.com/legal/fees/
...

Sheet Sales Log
A1: Sales Log
A2: Direct sales (website, Stripe, invoices, events): one row per order. Marketplaces and royalties (Etsy, TikTok, TpT, KDP, IngramSpark, Faire, merchant of record, affiliates): one row per channel per month from the monthly statement. Net payout is a formula. Grey italic EXAMPLE rows are excluded from every total - delete them when you start.
A4: Date | B4: Channel | C4: Order ID | D4: Product | E4: SKU | F4: Qty | G4: Gross | H4: Platform fees | I4: Shipping charged | J4: Sales tax collected | K4: Tax collected by marketplace? (Y/N) | L4: Net payout | M4: Buyer state / country | N4: Taxable in MD? (Y/N) | O4: Income account | P4: Payout ref (date or ID) | Q4: Notes | R4: Example row
A5: 46298 | B5: Etsy | C5: EXAMPLE-ETSY-2026-10 | D5: EXAMPLE - October Etsy statement (monthly summary row) | E5: various | F5: 18 | G5: 142 | H5: 21.5 | I5: 12 | J5: 9.8 | K5: Y | L5: =IF(G5="","",G5-H5+I5+IF(K5="N",J5,0)) -> 132.5 | M5: Various | O5: 4100 Sales - digital downloads (printables) | P5: Etsy deposit 11/01/2026 | Q5: EXAMPLE - made-up amounts to show the format | R5: EXAMPLE
A6: 46303 | B6: Shopify (website store) | C6: EXAMPLE-#1001 | D6: EXAMPLE - Play Before Pixels card deck | E6: PBP-DECK-01 | F6: 1 | G6: 24 | H6: 1 | I6: 5 | J6: 1.44 | K6: N | L6: =IF(G6="","",G6-H6+I6+IF(K6="N",J6,0)) -> 29.44 | M6: MD | N6: Y | O6: 4250 Sales - card deck | P6: Shopify payout 10/10/2026 | Q6: EXAMPLE - you collected MD tax, so it is in the payout and goes to 2200 | R6: EXAMPLE
A7: 46310 | B7: Stripe (website & invoices) | C7: EXAMPLE-INV-0001 | D7: EXAMPLE - Parent coaching session (audio) | E7: COACH-60 | F7: 1 | G7: 95 | H7: 3.06 | I7: 0 | J7: 0 | K7: N | L7: =IF(G7="","",G7-H7+I7+IF(K7="N",J7,0)) -> 91.94 | M7: MD | N7: N | O7: 4500 Coaching (services) | P7: Stripe payout 10/17/2026 | Q7: EXAMPLE - live coaching generally not taxable in MD (UNVERIFIED) | R7: EXAMPLE
A8: 46326 | B8: Amazon KDP | C8: EXAMPLE-KDP-2026-10-US | D8: EXAMPLE - October royalties, amazon.com | E8: all titles | F8: 12 | G8: 38.4 | H8: 0 | I8: 0 | J8: 0 | K8: Y | L8: =IF(G8="","",G8-H8+I8+IF(K8="N",J8,0)) -> 38.4 | M8: Various | O8: 4000 Book royalties - KDP | P8: Expected ~12/29/2026 | Q8: EXAMPLE - royalty earned; post Dr 1100 / Cr 4000 | R8: EXAMPLE
L9: =IF(G9="","",G9-H9+I9+IF(K9="N",J9,0))
L10: =IF(G10="","",G10-H10+I10+IF(K10="N",J10,0))
L11: =IF(G11="","",G11-H11+I11+IF(K11="N",J11,0))
L12: =IF(G12="","",G12-H12+I12+IF(K12="N",J12,0))
L13: =IF(G13="","",G13-H13+I13+IF(K13="N",J13,0))
L14: =IF(G14="","",G14-H14+I14+IF(K14="N",J14,0))
L15: =IF(G15="","",G15-H15+I15+IF(K15="N",J15,0))
L16: =IF(G16="","",G16-H16+I16+IF(K16="N",J16,0))
L17: =IF(G17="","",G17-H17+I17+IF(K17="N",J17,0))
L18: =IF(G18="","",G18-H18+I18+IF(K18="N",J18,0))
L19: =IF(G19="","",G19-H19+I19+IF(K19="N",J19,0))
L20: =IF(G20="","",G20-H20+I20+IF(K20="N",J20,0))
... L1004: =IF(G1004="","",G1004-H1004+I1004+IF(K1004="N",J1004,0))

Sheet Expenses
A1: Expenses
A2: Every cost the business pays: one row per receipt. Pick the category from the drop-down (it comes from the Chart of Accounts). Fees a platform already deducted from a payout go in the Sales Log, not here. Owner draws and tax payments are NOT expenses - never log them here.
A4: Date | B4: Vendor | C4: Category | D4: Amount | E4: Paid with | F4: Receipt link | G4: Notes | H4: 1099 contractor? (Y/N) | I4: W-9 on file? (Y/N) | J4: 1099-NEC watch | K4: Example row
A5: 46297 | B5: Printful | C5: 5100 COGS - POD fulfillment (Printful) | D5: 14.25 | E5: Business credit card | F5: https://drive.example/receipts/printful-1002 | G5: EXAMPLE - tee for an Etsy order (made-up amount) | H5: N | J5: =IF(AND(H5="Y",E5="Business checking (debit/ACH/check)"),"Counts toward 1099-NEC",IF(H5="Y","Paid by card/PayPal - 1099-K side","")) | K5: EXAMPLE
A6: 46301 | B6: IngramSpark | C6: 1200 Inventory - author copies & stock | D6: 60 | E6: Business credit card | F6: https://drive.example/receipts/ingram-1006 | G6: EXAMPLE - author copies for a school order (inventory) | H6: N | J6: =IF(AND(H6="Y",E6="Business checking (debit/ACH/check)"),"Counts toward 1099-NEC",IF(H6="Y","Paid by card/PayPal - 1099-K side","")) | K6: EXAMPLE
A7: 46315 | B7: EXAMPLE Illustrator (contractor) | C7: 6500 Contract labor (1099 watch) | D7: 400 | E7: Business checking (debit/ACH/check) | F7: https://drive.example/receipts/illustrator-inv-7 | G7: EXAMPLE - spot illustrations; W-9 collected first | H7: Y | I7: Y | J7: =IF(AND(H7="Y",E7="Business checking (debit/ACH/check)"),"Counts toward 1099-NEC",IF(H7="Y","Paid by card/PayPal - 1099-K side","")) -> Counts toward 1099-NEC | K7: EXAMPLE
J8: =IF(AND(H8="Y",E8="Business checking (debit/ACH/check)"),"Counts toward 1099-NEC",IF(H8="Y","Paid by card/PayPal - 1099-K side",""))
J9: =IF(AND(H9="Y",E9="Business checking (debit/ACH/check)"),"Counts toward 1099-NEC",IF(H9="Y","Paid by card/PayPal - 1099-K side",""))
J10: =IF(AND(H10="Y",E10="Business checking (debit/ACH/check)"),"Counts toward 1099-NEC",IF(H10="Y","Paid by card/PayPal - 1099-K side",""))
J11: =IF(AND(H11="Y",E11="Business checking (debit/ACH/check)"),"Counts toward 1099-NEC",IF(H11="Y","Paid by card/PayPal - 1099-K side",""))
J12: =IF(AND(H12="Y",E12="Business checking (debit/ACH/check)"),"Counts toward 1099-NEC",IF(H12="Y","Paid by card/PayPal - 1099-K side",""))
J13: =IF(AND(H13="Y",E13="Business checking (debit/ACH/check)"),"Counts toward 1099-NEC",IF(H13="Y","Paid by card/PayPal - 1099-K side",""))
J14: =IF(AND(H14="Y",E14="Business checking (debit/ACH/check)"),"Counts toward 1099-NEC",IF(H14="Y","Paid by card/PayPal - 1099-K side",""))
J15: =IF(AND(H15="Y",E15="Business checking (debit/ACH/check)"),"Counts toward 1099-NEC",IF(H15="Y","Paid by card/PayPal - 1099-K side",""))
J16: =IF(AND(H16="Y",E16="Business checking (debit/ACH/check)"),"Counts toward 1099-NEC",IF(H16="Y","Paid by card/PayPal - 1099-K side",""))
J17: =IF(AND(H17="Y",E17="Business checking (debit/ACH/check)"),"Counts toward 1099-NEC",IF(H17="Y","Paid by card/PayPal - 1099-K side",""))
J18: =IF(AND(H18="Y",E18="Business checking (debit/ACH/check)"),"Counts toward 1099-NEC",IF(H18="Y","Paid by card/PayPal - 1099-K side",""))
J19: =IF(AND(H19="Y",E19="Business checking (debit/ACH/check)"),"Counts toward 1099-NEC",IF(H19="Y","Paid by card/PayPal - 1099-K side",""))
... J1004: =IF(AND(H1004="Y",E1004="Business checking (debit/ACH/check)"),"Counts toward 1099-NEC",IF(H1004="Y","Paid by card/PayPal - 1099-K side",""))

Sheet Payouts Reconciliation
A1: Payouts Reconciliation
A2: One row per payout. Type what the platform says it paid, then the deposit you see on the business checking statement. Bank deposit match turns MATCHED, CHECK or WAITING. A platform payout routed through PayPal is a transfer, not new income: log the platform payout here and match it to the PayPal-to-checking transfer.
A4: Channel | B4: Payout date | C4: Amount | D4: Payout / settlement ID | E4: Period start | F4: Period end | G4: Bank deposit date | H4: Bank deposit amount | I4: Difference | J4: Bank deposit match | K4: Sales Log net for period | L4: Posted in QBO/Xero? (Y/N) | M4: Report saved (link) | N4: Notes | O4: Example row
A5: Etsy | B5: 46327 | C5: 132.5 | D5: EXAMPLE-ETSY-DEP-1101 | E5: 46296 | F5: 46326 | G5: 46329 | H5: 132.5 | I5: =IF(OR(C5="",H5=""),"",C5-H5) -> 0 | J5: =IF(C5="","",IF(H5="","WAITING",IF(ABS(C5-H5)<0.005,"MATCHED","CHECK"))) -> MATCHED | K5: =IF(OR(A5="",E5="",F5=""),"",SUMIFS('Sales Log'!$L$5:$L$1004,'Sales Log'!$B$5:$B$1004,A5,'Sales Log'!$A$5:$A$1004,">="&E5,'Sales Log'!$A$5:$A$1004,"<="&F5,'Sales Log'!$R$5:$R$1004,IF(O5="EXAMPLE","EXAMPLE","<>EXAMPLE"))) -> 132.5 | L5: Y | M5: https://drive.example/etsy/2026-10.csv | N5: EXAMPLE | O5: EXAMPLE
A6: Shopify (website store) | B6: 46305 | C6: 29.44 | D6: EXAMPLE-SHOP-PO-1010 | E6: 46303 | F6: 46303 | G6: 46308 | H6: 29.4 | I6: =IF(OR(C6="",H6=""),"",C6-H6) -> 0.04 | J6: =IF(C6="","",IF(H6="","WAITING",IF(ABS(C6-H6)<0.005,"MATCHED","CHECK"))) -> CHECK | K6: =IF(OR(A6="",E6="",F6=""),"",SUMIFS('Sales Log'!$L$5:$L$1004,'Sales Log'!$B$5:$B$1004,A6,'Sales Log'!$A$5:$A$1004,">="&E6,'Sales Log'!$A$5:$A$1004,"<="&F6,'Sales Log'!$R$5:$R$1004,IF(O6="EXAMPLE","EXAMPLE","<>EXAMPLE"))) -> 29.44 | L6: N | N6: EXAMPLE - 4 cents off: find out why | O6: EXAMPLE
A7: Amazon KDP | B7: 46385 | C7: 38.4 | D7: EXAMPLE-KDP-EFT | E7: 46296 | F7: 46326 | I7: =IF(OR(C7="",H7=""),"",C7-H7) | J7: =IF(C7="","",IF(H7="","WAITING",IF(ABS(C7-H7)<0.005,"MATCHED","CHECK"))) -> WAITING | K7: =IF(OR(A7="",E7="",F7=""),"",SUMIFS('Sales Log'!$L$5:$L$1004,'Sales Log'!$B$5:$B$1004,A7,'Sales Log'!$A$5:$A$1004,">="&E7,'Sales Log'!$A$5:$A$1004,"<="&F7,'Sales Log'!$R$5:$R$1004,IF(O7="EXAMPLE","EXAMPLE","<>EXAMPLE"))) -> 38.4 | L7: N | N7: EXAMPLE - not arrived yet | O7: EXAMPLE
I8: =IF(OR(C8="",H8=""),"",C8-H8) | J8: =IF(C8="","",IF(H8="","WAITING",IF(ABS(C8-H8)<0.005,"MATCHED","CHECK"))) | K8: =IF(OR(A8="",E8="",F8=""),"",SUMIFS('Sales Log'!$L$5:$L$1004,'Sales Log'!$B$5:$B$1004,A8,'Sales Log'!$A$5:$A$1004,">="&E8,'Sales Log'!$A$5:$A$1004,"<="&F8,'Sales Log'!$R$5:$R$1004,IF(O8="EXAMPLE","EXAMPLE","<>EXAMPLE")))
I9: =IF(OR(C9="",H9=""),"",C9-H9) | J9: =IF(C9="","",IF(H9="","WAITING",IF(ABS(C9-H9)<0.005,"MATCHED","CHECK"))) | K9: =IF(OR(A9="",E9="",F9=""),"",SUMIFS('Sales Log'!$L$5:$L$1004,'Sales Log'!$B$5:$B$1004,A9,'Sales Log'!$A$5:$A$1004,">="&E9,'Sales Log'!$A$5:$A$1004,"<="&F9,'Sales Log'!$R$5:$R$1004,IF(O9="EXAMPLE","EXAMPLE","<>EXAMPLE")))
I10: =IF(OR(C10="",H10=""),"",C10-H10) | J10: =IF(C10="","",IF(H10="","WAITING",IF(ABS(C10-H10)<0.005,"MATCHED","CHECK"))) | K10: =IF(OR(A10="",E10="",F10=""),"",SUMIFS('Sales Log'!$L$5:$L$1004,'Sales Log'!$B$5:$B$1004,A10,'Sales Log'!$A$5:$A$1004,">="&E10,'Sales Log'!$A$5:$A$1004,"<="&F10,'Sales Log'!$R$5:$R$1004,IF(O10="EXAMPLE","EXAMPLE","<>EXAMPLE")))
I11: =IF(OR(C11="",H11=""),"",C11-H11) | J11: =IF(C11="","",IF(H11="","WAITING",IF(ABS(C11-H11)<0.005,"MATCHED","CHECK"))) | K11: =IF(OR(A11="",E11="",F11=""),"",SUMIFS('Sales Log'!$L$5:$L$1004,'Sales Log'!$B$5:$B$1004,A11,'Sales Log'!$A$5:$A$1004,">="&E11,'Sales Log'!$A$5:$A$1004,"<="&F11,'Sales Log'!$R$5:$R$1004,IF(O11="EXAMPLE","EXAMPLE","<>EXAMPLE")))
I12: =IF(OR(C12="",H12=""),"",C12-H12) | J12: =IF(C12="","",IF(H12="","WAITING",IF(ABS(C12-H12)<0.005,"MATCHED","CHECK"))) | K12: =IF(OR(A12="",E12="",F12=""),"",SUMIFS('Sales Log'!$L$5:$L$1004,'Sales Log'!$B$5:$B$1004,A12,'Sales Log'!$A$5:$A$1004,">="&E12,'Sales Log'!$A$5:$A$1004,"<="&F12,'Sales Log'!$R$5:$R$1004,IF(O12="EXAMPLE","EXAMPLE","<>EXAMPLE")))
I13: =IF(OR(C13="",H13=""),"",C13-H13) | J13: =IF(C13="","",IF(H13="","WAITING",IF(ABS(C13-H13)<0.005,"MATCHED","CHECK"))) | K13: =IF(OR(A13="",E13="",F13=""),"",SUMIFS('Sales Log'!$L$5:$L$1004,'Sales Log'!$B$5:$B$1004,A13,'Sales Log'!$A$5:$A$1004,">="&E13,'Sales Log'!$A$5:$A$1004,"<="&F13,'Sales Log'!$R$5:$R$1004,IF(O13="EXAMPLE","EXAMPLE","<>EXAMPLE")))
I14: =IF(OR(C14="",H14=""),"",C14-H14) | J14: =IF(C14="","",IF(H14="","WAITING",IF(ABS(C14-H14)<0.005,"MATCHED","CHECK"))) | K14: =IF(OR(A14="",E14="",F14=""),"",SUMIFS('Sales Log'!$L$5:$L$1004,'Sales Log'!$B$5:$B$1004,A14,'Sales Log'!$A$5:$A$1004,">="&E14,'Sales Log'!$A$5:$A$1004,"<="&F14,'Sales Log'!$R$5:$R$1004,IF(O14="EXAMPLE","EXAMPLE","<>EXAMPLE")))
I15: =IF(OR(C15="",H15=""),"",C15-H15) | J15: =IF(C15="","",IF(H15="","WAITING",IF(ABS(C15-H15)<0.005,"MATCHED","CHECK"))) | K15: =IF(OR(A15="",E15="",F15=""),"",SUMIFS('Sales Log'!$L$5:$L$1004,'Sales Log'!$B$5:$B$1004,A15,'Sales Log'!$A$5:$A$1004,">="&E15,'Sales Log'!$A$5:$A$1004,"<="&F15,'Sales Log'!$R$5:$R$1004,IF(O15="EXAMPLE","EXAMPLE","<>EXAMPLE")))
I16: =IF(OR(C16="",H16=""),"",C16-H16) | J16: =IF(C16="","",IF(H16="","WAITING",IF(ABS(C16-H16)<0.005,"MATCHED","CHECK"))) | K16: =IF(OR(A16="",E16="",F16=""),"",SUMIFS('Sales Log'!$L$5:$L$1004,'Sales Log'!$B$5:$B$1004,A16,'Sales Log'!$A$5:$A$1004,">="&E16,'Sales Log'!$A$5:$A$1004,"<="&F16,'Sales Log'!$R$5:$R$1004,IF(O16="EXAMPLE","EXAMPLE","<>EXAMPLE")))
I17: =IF(OR(C17="",H17=""),"",C17-H17) | J17: =IF(C17="","",IF(H17="","WAITING",IF(ABS(C17-H17)<0.005,"MATCHED","CHECK"))) | K17: =IF(OR(A17="",E17="",F17=""),"",SUMIFS('Sales Log'!$L$5:$L$1004,'Sales Log'!$B$5:$B$1004,A17,'Sales Log'!$A$5:$A$1004,">="&E17,'Sales Log'!$A$5:$A$1004,"<="&F17,'Sales Log'!$R$5:$R$1004,IF(O17="EXAMPLE","EXAMPLE","<>EXAMPLE")))
I18: =IF(OR(C18="",H18=""),"",C18-H18) | J18: =IF(C18="","",IF(H18="","WAITING",IF(ABS(C18-H18)<0.005,"MATCHED","CHECK"))) | K18: =IF(OR(A18="",E18="",F18=""),"",SUMIFS('Sales Log'!$L$5:$L$1004,'Sales Log'!$B$5:$B$1004,A18,'Sales Log'!$A$5:$A$1004,">="&E18,'Sales Log'!$A$5:$A$1004,"<="&F18,'Sales Log'!$R$5:$R$1004,IF(O18="EXAMPLE","EXAMPLE","<>EXAMPLE")))
I19: =IF(OR(C19="",H19=""),"",C19-H19) | J19: =IF(C19="","",IF(H19="","WAITING",IF(ABS(C19-H19)<0.005,"MATCHED","CHECK"))) | K19: =IF(OR(A19="",E19="",F19=""),"",SUMIFS('Sales Log'!$L$5:$L$1004,'Sales Log'!$B$5:$B$1004,A19,'Sales Log'!$A$5:$A$1004,">="&E19,'Sales Log'!$A$5:$A$1004,"<="&F19,'Sales Log'!$R$5:$R$1004,IF(O19="EXAMPLE","EXAMPLE","<>EXAMPLE")))
... I504: =IF(OR(C504="",H504=""),"",C504-H504) | J504: =IF(C504="","",IF(H504="","WAITING",IF(ABS(C504-H504)<0.005,"MATCHED","CHECK"))) | K504: =IF(OR(A504="",E504="",F504=""),"",SUMIFS('Sales Log'!$L$5:$L$1004,'Sales Log'!$B$5:$B$1004,A504,'Sales Log'!$A$5:$A$1004,">="&E504,'Sales Log'!$A$5:$A$1004,"<="&F504,'Sales Log'!$R$5:$R$1004,IF(O504="EXAMPLE","EXAMPLE","<>EXAMPLE")))

Sheet Channel Summary
A1: Channel Summary
A2: Everything on this tab is a formula (SUMIFS by channel and month) - do not type in the grey/white grid. Change the tax year in B3 to reuse the workbook next year. EXAMPLE rows are excluded.
A3: Tax year | B3: 2026
A5: Gross sales (before fees; excludes shipping and sales tax)
A6: Channel | B6: =DATE($B$3,1,1) -> 46023 | C6: =DATE($B$3,2,1) -> 46054 | D6: =DATE($B$3,3,1) -> 46082 | E6: =DATE($B$3,4,1) -> 46113 | F6: =DATE($B$3,5,1) -> 46143 | G6: =DATE($B$3,6,1) -> 46174 | H6: =DATE($B$3,7,1) -> 46204 | I6: =DATE($B$3,8,1) -> 46235 | J6: =DATE($B$3,9,1) -> 46266 | K6: =DATE($B$3,10,1) -> 46296 | L6: =DATE($B$3,11,1) -> 46327 | M6: =DATE($B$3,12,1) -> 46357 | N6: Total
A7: ='Chart of Accounts'!$A$66 -> Amazon KDP | B7: =SUMIFS('Sales Log'!$G$5:$G$1004,'Sales Log'!$A$5:$A$1004,">="&B$6,'Sales Log'!$A$5:$A$1004,"<"&DATE(YEAR(B$6),MONTH(B$6)+1,1),'Sales Log'!$B$5:$B$1004,$A7,'Sales Log'!$R$5:$R$1004,"<>EXAMPLE") -> 0 | C7: =SUMIFS('Sales Log'!$G$5:$G$1004,'Sales Log'!$A$5:$A$1004,">="&C$6,'Sales Log'!$A$5:$A$1004,"<"&DATE(YEAR(C$6),MONTH(C$6)+1,1),'Sales Log'!$B$5:$B$1004,$A7,'Sales Log'!$R$5:$R$1004,"<>EXAMPLE") -> 0 | D7: =SUMIFS('Sales Log'!$G$5:$G$1004,'Sales Log'!$A$5:$A$1004,">="&D$6,'Sales Log'!$A$5:$A$1004,"<"&DATE(YEAR(D$6),MONTH(D$6)+1,1),'Sales Log'!$B$5:$B$1004,$A7,'Sales Log'!$R$5:$R$1004,"<>EXAMPLE") -> 0 | E7: =SUMIFS('Sales Log'!$G$5:$G$1004,'Sales Log'!$A$5:$A$1004,">="&E$6,'Sales Log'!$A$5:$A$1004,"<"&DATE(YEAR(E$6),MONTH(E$6)+1,1),'Sales Log'!$B$5:$B$1004,$A7,'Sales Log'!$R$5:$R$1004,"<>EXAMPLE") -> 0 | F7: =SUMIFS('Sales Log'!$G$5:$G$1004,'Sales Log'!$A$5:$A$1004,">="&F$6,'Sales Log'!$A$5:$A$1004,"<"&DATE(YEAR(F$6),MONTH(F$6)+1,1),'Sales Log'!$B$5:$B$1004,$A7,'Sales Log'!$R$5:$R$1004,"<>EXAMPLE") -> 0 | G7: =SUMIFS('Sales Log'!$G$5:$G$1004,'Sales Log'!$A$5:$A$1004,">="&G$6,'Sales Log'!$A$5:$A$1004,"<"&DATE(YEAR(G$6),MONTH(G$6)+1,1),'Sales Log'!$B$5:$B$1004,$A7,'Sales Log'!$R$5:$R$1004,"<>EXAMPLE") -> 0 | H7: =SUMIFS('Sales Log'!$G$5:$G$1004,'Sales Log'!$A$5:$A$1004,">="&H$6,'Sales Log'!$A$5:$A$1004,"<"&DATE(YEAR(H$6),MONTH(H$6)+1,1),'Sales Log'!$B$5:$B$1004,$A7,'Sales Log'!$R$5:$R$1004,"<>EXAMPLE") -> 0 | I7: =SUMIFS('Sales Log'!$G$5:$G$1004,'Sales Log'!$A$5:$A$1004,">="&I$6,'Sales Log'!$A$5:$A$1004,"<"&DATE(YEAR(I$6),MONTH(I$6)+1,1),'Sales Log'!$B$5:$B$1004,$A7,'Sales Log'!$R$5:$R$1004,"<>EXAMPLE") -> 0 | ... M7: =SUMIFS('Sales Log'!$G$5:$G$1004,'Sales Log'!$A$5:$A$1004,">="&M$6,'Sales Log'!$A$5:$A$1004,"<"&DATE(YEAR(M$6),MONTH(M$6)+1,1),'Sales Log'!$B$5:$B$1004,$A7,'Sales Log'!$R$5:$R$1004,"<>EXAMPLE") -> 0 | N7: =SUM(B7:M7) -> 0
A8: ='Chart of Accounts'!$A$67 -> IngramSpark | B8: =SUMIFS('Sales Log'!$G$5:$G$1004,'Sales Log'!$A$5:$A$1004,">="&B$6,'Sales Log'!$A$5:$A$1004,"<"&DATE(YEAR(B$6),MONTH(B$6)+1,1),'Sales Log'!$B$5:$B$1004,$A8,'Sales Log'!$R$5:$R$1004,"<>EXAMPLE") -> 0 | C8: =SUMIFS('Sales Log'!$G$5:$G$1004,'Sales Log'!$A$5:$A$1004,">="&C$6,'Sales Log'!$A$5:$A$1004,"<"&DATE(YEAR(C$6),MONTH(C$6)+1,1),'Sales Log'!$B$5:$B$1004,$A8,'Sales Log'!$R$5:$R$1004,"<>EXAMPLE") -> 0 | D8: =SUMIFS('Sales Log'!$G$5:$G$1004,'Sales Log'!$A$5:$A$1004,">="&D$6,'Sales Log'!$A$5:$A$1004,"<"&DATE(YEAR(D$6),MONTH(D$6)+1,1),'Sales Log'!$B$5:$B$1004,$A8,'Sales Log'!$R$5:$R$1004,"<>EXAMPLE") -> 0 | E8: =SUMIFS('Sales Log'!$G$5:$G$1004,'Sales Log'!$A$5:$A$1004,">="&E$6,'Sales Log'!$A$5:$A$1004,"<"&DATE(YEAR(E$6),MONTH(E$6)+1,1),'Sales Log'!$B$5:$B$1004,$A8,'Sales Log'!$R$5:$R$1004,"<>EXAMPLE") -> 0 | F8: =SUMIFS('Sales Log'!$G$5:$G$1004,'Sales Log'!$A$5:$A$1004,">="&F$6,'Sales Log'!$A$5:$A$1004,"<"&DATE(YEAR(F$6),MONTH(F$6)+1,1),'Sales Log'!$B$5:$B$1004,$A8,'Sales Log'!$R$5:$R$1004,"<>EXAMPLE") -> 0 | G8: =SUMIFS('Sales Log'!$G$5:$G$1004,'Sales Log'!$A$5:$A$1004,">="&G$6,'Sales Log'!$A$5:$A$1004,"<"&DATE(YEAR(G$6),MONTH(G$6)+1,1),'Sales Log'!$B$5:$B$1004,$A8,'Sales Log'!$R$5:$R$1004,"<>EXAMPLE") -> 0 | H8: =SUMIFS('Sales Log'!$G$5:$G$1004,'Sales Log'!$A$5:$A$1004,">="&H$6,'Sales Log'!$A$5:$A$1004,"<"&DATE(YEAR(H$6),MONTH(H$6)+1,1),'Sales Log'!$B$5:$B$1004,$A8,'Sales Log'!$R$5:$R$1004,"<>EXAMPLE") -> 0 | I8: =SUMIFS('Sales Log'!$G$5:$G$1004,'Sales Log'!$A$5:$A$1004,">="&I$6,'Sales Log'!$A$5:$A$1004,"<"&DATE(YEAR(I$6),MONTH(I$6)+1,1),'Sales Log'!$B$5:$B$1004,$A8,'Sales Log'!$R$5:$R$1004,"<>EXAMPLE") -> 0 | ... M8: =SUMIFS('Sales Log'!$G$5:$G$1004,'Sales Log'!$A$5:$A$1004,">="&M$6,'Sales Log'!$A$5:$A$1004,"<"&DATE(YEAR(M$6),MONTH(M$6)+1,1),'Sales Log'!$B$5:$B$1004,$A8,'Sales Log'!$R$5:$R$1004,"<>EXAMPLE") -> 0 | N8: =SUM(B8:M8) -> 0
A9: ='Chart of Accounts'!$A$68 -> Etsy | B9: =SUMIFS('Sales Log'!$G$5:$G$1004,'Sales Log'!$A$5:$A$1004,">="&B$6,'Sales Log'!$A$5:$A$1004,"<"&DATE(YEAR(B$6),MONTH(B$6)+1,1),'Sales Log'!$B$5:$B$1004,$A9,'Sales Log'!$R$5:$R$1004,"<>EXAMPLE") -> 0 | C9: =SUMIFS('Sales Log'!$G$5:$G$1004,'Sales Log'!$A$5:$A$1004,">="&C$6,'Sales Log'!$A$5:$A$1004,"<"&DATE(YEAR(C$6),MONTH(C$6)+1,1),'Sales Log'!$B$5:$B$1004,$A9,'Sales Log'!$R$5:$R$1004,"<>EXAMPLE") -> 0 | D9: =SUMIFS('Sales Log'!$G$5:$G$1004,'Sales Log'!$A$5:$A$1004,">="&D$6,'Sales Log'!$A$5:$A$1004,"<"&DATE(YEAR(D$6),MONTH(D$6)+1,1),'Sales Log'!$B$5:$B$1004,$A9,'Sales Log'!$R$5:$R$1004,"<>EXAMPLE") -> 0 | E9: =SUMIFS('Sales Log'!$G$5:$G$1004,'Sales Log'!$A$5:$A$1004,">="&E$6,'Sales Log'!$A$5:$A$1004,"<"&DATE(YEAR(E$6),MONTH(E$6)+1,1),'Sales Log'!$B$5:$B$1004,$A9,'Sales Log'!$R$5:$R$1004,"<>EXAMPLE") -> 0 | F9: =SUMIFS('Sales Log'!$G$5:$G$1004,'Sales Log'!$A$5:$A$1004,">="&F$6,'Sales Log'!$A$5:$A$1004,"<"&DATE(YEAR(F$6),MONTH(F$6)+1,1),'Sales Log'!$B$5:$B$1004,$A9,'Sales Log'!$R$5:$R$1004,"<>EXAMPLE") -> 0 | G9: =SUMIFS('Sales Log'!$G$5:$G$1004,'Sales Log'!$A$5:$A$1004,">="&G$6,'Sales Log'!$A$5:$A$1004,"<"&DATE(YEAR(G$6),MONTH(G$6)+1,1),'Sales Log'!$B$5:$B$1004,$A9,'Sales Log'!$R$5:$R$1004,"<>EXAMPLE") -> 0 | H9: =SUMIFS('Sales Log'!$G$5:$G$1004,'Sales Log'!$A$5:$A$1004,">="&H$6,'Sales Log'!$A$5:$A$1004,"<"&DATE(YEAR(H$6),MONTH(H$6)+1,1),'Sales Log'!$B$5:$B$1004,$A9,'Sales Log'!$R$5:$R$1004,"<>EXAMPLE") -> 0 | I9: =SUMIFS('Sales Log'!$G$5:$G$1004,'Sales Log'!$A$5:$A$1004,">="&I$6,'Sales Log'!$A$5:$A$1004,"<"&DATE(YEAR(I$6),MONTH(I$6)+1,1),'Sales Log'!$B$5:$B$1004,$A9,'Sales Log'!$R$5:$R$1004,"<>EXAMPLE") -> 0 | ... M9: =SUMIFS('Sales Log'!$G$5:$G$1004,'Sales Log'!$A$5:$A$1004,">="&M$6,'Sales Log'!$A$5:$A$1004,"<"&DATE(YEAR(M$6),MONTH(M$6)+1,1),'Sales Log'!$B$5:$B$1004,$A9,'Sales Log'!$R$5:$R$1004,"<>EXAMPLE") -> 0 | N9: =SUM(B9:M9) -> 0
A10: ='Chart of Accounts'!$A$69 -> Teachers Pay Teachers | B10: =SUMIFS('Sales Log'!$G$5:$G$1004,'Sales Log'!$A$5:$A$1004,">="&B$6,'Sales Log'!$A$5:$A$1004,"<"&DATE(YEAR(B$6),MONTH(B$6)+1,1),'Sales Log'!$B$5:$B$1004,$A10,'Sales Log'!$R$5:$R$1004,"<>EXAMPLE") -> 0 | C10: =SUMIFS('Sales Log'!$G$5:$G$1004,'Sales Log'!$A$5:$A$1004,">="&C$6,'Sales Log'!$A$5:$A$1004,"<"&DATE(YEAR(C$6),MONTH(C$6)+1,1),'Sales Log'!$B$5:$B$1004,$A10,'Sales Log'!$R$5:$R$1004,"<>EXAMPLE") -> 0 | D10: =SUMIFS('Sales Log'!$G$5:$G$1004,'Sales Log'!$A$5:$A$1004,">="&D$6,'Sales Log'!$A$5:$A$1004,"<"&DATE(YEAR(D$6),MONTH(D$6)+1,1),'Sales Log'!$B$5:$B$1004,$A10,'Sales Log'!$R$5:$R$1004,"<>EXAMPLE") -> 0 | E10: =SUMIFS('Sales Log'!$G$5:$G$1004,'Sales Log'!$A$5:$A$1004,">="&E$6,'Sales Log'!$A$5:$A$1004,"<"&DATE(YEAR(E$6),MONTH(E$6)+1,1),'Sales Log'!$B$5:$B$1004,$A10,'Sales Log'!$R$5:$R$1004,"<>EXAMPLE") -> 0 | F10: =SUMIFS('Sales Log'!$G$5:$G$1004,'Sales Log'!$A$5:$A$1004,">="&F$6,'Sales Log'!$A$5:$A$1004,"<"&DATE(YEAR(F$6),MONTH(F$6)+1,1),'Sales Log'!$B$5:$B$1004,$A10,'Sales Log'!$R$5:$R$1004,"<>EXAMPLE") -> 0 | G10: =SUMIFS('Sales Log'!$G$5:$G$1004,'Sales Log'!$A$5:$A$1004,">="&G$6,'Sales Log'!$A$5:$A$1004,"<"&DATE(YEAR(G$6),MONTH(G$6)+1,1),'Sales Log'!$B$5:$B$1004,$A10,'Sales Log'!$R$5:$R$1004,"<>EXAMPLE") -> 0 | H10: =SUMIFS('Sales Log'!$G$5:$G$1004,'Sales Log'!$A$5:$A$1004,">="&H$6,'Sales Log'!$A$5:$A$1004,"<"&DATE(YEAR(H$6),MONTH(H$6)+1,1),'Sales Log'!$B$5:$B$1004,$A10,'Sales Log'!$R$5:$R$1004,"<>EXAMPLE") -> 0 | I10: =SUMIFS('Sales Log'!$G$5:$G$1004,'Sales Log'!$A$5:$A$1004,">="&I$6,'Sales Log'!$A$5:$A$1004,"<"&DATE(YEAR(I$6),MONTH(I$6)+1,1),'Sales Log'!$B$5:$B$1004,$A10,'Sales Log'!$R$5:$R$1004,"<>EXAMPLE") -> 0 | ... M10: =SUMIFS('Sales Log'!$G$5:$G$1004,'Sales Log'!$A$5:$A$1004,">="&M$6,'Sales Log'!$A$5:$A$1004,"<"&DATE(YEAR(M$6),MONTH(M$6)+1,1),'Sales Log'!$B$5:$B$1004,$A10,'Sales Log'!$R$5:$R$1004,"<>EXAMPLE") -> 0 | N10: =SUM(B10:M10) -> 0
A11: ='Chart of Accounts'!$A$70 -> TikTok Shop | B11: =SUMIFS('Sales Log'!$G$5:$G$1004,'Sales Log'!$A$5:$A$1004,">="&B$6,'Sales Log'!$A$5:$A$1004,"<"&DATE(YEAR(B$6),MONTH(B$6)+1,1),'Sales Log'!$B$5:$B$1004,$A11,'Sales Log'!$R$5:$R$1004,"<>EXAMPLE") -> 0 | C11: =SUMIFS('Sales Log'!$G$5:$G$1004,'Sales Log'!$A$5:$A$1004,">="&C$6,'Sales Log'!$A$5:$A$1004,"<"&DATE(YEAR(C$6),MONTH(C$6)+1,1),'Sales Log'!$B$5:$B$1004,$A11,'Sales Log'!$R$5:$R$1004,"<>EXAMPLE") -> 0 | D11: =SUMIFS('Sales Log'!$G$5:$G$1004,'Sales Log'!$A$5:$A$1004,">="&D$6,'Sales Log'!$A$5:$A$1004,"<"&DATE(YEAR(D$6),MONTH(D$6)+1,1),'Sales Log'!$B$5:$B$1004,$A11,'Sales Log'!$R$5:$R$1004,"<>EXAMPLE") -> 0 | E11: =SUMIFS('Sales Log'!$G$5:$G$1004,'Sales Log'!$A$5:$A$1004,">="&E$6,'Sales Log'!$A$5:$A$1004,"<"&DATE(YEAR(E$6),MONTH(E$6)+1,1),'Sales Log'!$B$5:$B$1004,$A11,'Sales Log'!$R$5:$R$1004,"<>EXAMPLE") -> 0 | F11: =SUMIFS('Sales Log'!$G$5:$G$1004,'Sales Log'!$A$5:$A$1004,">="&F$6,'Sales Log'!$A$5:$A$1004,"<"&DATE(YEAR(F$6),MONTH(F$6)+1,1),'Sales Log'!$B$5:$B$1004,$A11,'Sales Log'!$R$5:$R$1004,"<>EXAMPLE") -> 0 | G11: =SUMIFS('Sales Log'!$G$5:$G$1004,'Sales Log'!$A$5:$A$1004,">="&G$6,'Sales Log'!$A$5:$A$1004,"<"&DATE(YEAR(G$6),MONTH(G$6)+1,1),'Sales Log'!$B$5:$B$1004,$A11,'Sales Log'!$R$5:$R$1004,"<>EXAMPLE") -> 0 | H11: =SUMIFS('Sales Log'!$G$5:$G$1004,'Sales Log'!$A$5:$A$1004,">="&H$6,'Sales Log'!$A$5:$A$1004,"<"&DATE(YEAR(H$6),MONTH(H$6)+1,1),'Sales Log'!$B$5:$B$1004,$A11,'Sales Log'!$R$5:$R$1004,"<>EXAMPLE") -> 0 | I11: =SUMIFS('Sales Log'!$G$5:$G$1004,'Sales Log'!$A$5:$A$1004,">="&I$6,'Sales Log'!$A$5:$A$1004,"<"&DATE(YEAR(I$6),MONTH(I$6)+1,1),'Sales Log'!$B$5:$B$1004,$A11,'Sales Log'!$R$5:$R$1004,"<>EXAMPLE") -> 0 | ... M11: =SUMIFS('Sales Log'!$G$5:$G$1004,'Sales Log'!$A$5:$A$1004,">="&M$6,'Sales Log'!$A$5:$A$1004,"<"&DATE(YEAR(M$6),MONTH(M$6)+1,1),'Sales Log'!$B$5:$B$1004,$A11,'Sales Log'!$R$5:$R$1004,"<>EXAMPLE") -> 0 | N11: =SUM(B11:M11) -> 0
A12: ='Chart of Accounts'!$A$71 -> Shopify (website store) | B12: =SUMIFS('Sales Log'!$G$5:$G$1004,'Sales Log'!$A$5:$A$1004,">="&B$6,'Sales Log'!$A$5:$A$1004,"<"&DATE(YEAR(B$6),MONTH(B$6)+1,1),'Sales Log'!$B$5:$B$1004,$A12,'Sales Log'!$R$5:$R$1004,"<>EXAMPLE") -> 0 | C12: =SUMIFS('Sales Log'!$G$5:$G$1004,'Sales Log'!$A$5:$A$1004,">="&C$6,'Sales Log'!$A$5:$A$1004,"<"&DATE(YEAR(C$6),MONTH(C$6)+1,1),'Sales Log'!$B$5:$B$1004,$A12,'Sales Log'!$R$5:$R$1004,"<>EXAMPLE") -> 0 | D12: =SUMIFS('Sales Log'!$G$5:$G$1004,'Sales Log'!$A$5:$A$1004,">="&D$6,'Sales Log'!$A$5:$A$1004,"<"&DATE(YEAR(D$6),MONTH(D$6)+1,1),'Sales Log'!$B$5:$B$1004,$A12,'Sales Log'!$R$5:$R$1004,"<>EXAMPLE") -> 0 | E12: =SUMIFS('Sales Log'!$G$5:$G$1004,'Sales Log'!$A$5:$A$1004,">="&E$6,'Sales Log'!$A$5:$A$1004,"<"&DATE(YEAR(E$6),MONTH(E$6)+1,1),'Sales Log'!$B$5:$B$1004,$A12,'Sales Log'!$R$5:$R$1004,"<>EXAMPLE") -> 0 | F12: =SUMIFS('Sales Log'!$G$5:$G$1004,'Sales Log'!$A$5:$A$1004,">="&F$6,'Sales Log'!$A$5:$A$1004,"<"&DATE(YEAR(F$6),MONTH(F$6)+1,1),'Sales Log'!$B$5:$B$1004,$A12,'Sales Log'!$R$5:$R$1004,"<>EXAMPLE") -> 0 | G12: =SUMIFS('Sales Log'!$G$5:$G$1004,'Sales Log'!$A$5:$A$1004,">="&G$6,'Sales Log'!$A$5:$A$1004,"<"&DATE(YEAR(G$6),MONTH(G$6)+1,1),'Sales Log'!$B$5:$B$1004,$A12,'Sales Log'!$R$5:$R$1004,"<>EXAMPLE") -> 0 | H12: =SUMIFS('Sales Log'!$G$5:$G$1004,'Sales Log'!$A$5:$A$1004,">="&H$6,'Sales Log'!$A$5:$A$1004,"<"&DATE(YEAR(H$6),MONTH(H$6)+1,1),'Sales Log'!$B$5:$B$1004,$A12,'Sales Log'!$R$5:$R$1004,"<>EXAMPLE") -> 0 | I12: =SUMIFS('Sales Log'!$G$5:$G$1004,'Sales Log'!$A$5:$A$1004,">="&I$6,'Sales Log'!$A$5:$A$1004,"<"&DATE(YEAR(I$6),MONTH(I$6)+1,1),'Sales Log'!$B$5:$B$1004,$A12,'Sales Log'!$R$5:$R$1004,"<>EXAMPLE") -> 0 | ... M12: =SUMIFS('Sales Log'!$G$5:$G$1004,'Sales Log'!$A$5:$A$1004,">="&M$6,'Sales Log'!$A$5:$A$1004,"<"&DATE(YEAR(M$6),MONTH(M$6)+1,1),'Sales Log'!$B$5:$B$1004,$A12,'Sales Log'!$R$5:$R$1004,"<>EXAMPLE") -> 0 | N12: =SUM(B12:M12) -> 0
A13: ='Chart of Accounts'!$A$72 -> Stripe (website & invoices) | B13: =SUMIFS('Sales Log'!$G$5:$G$1004,'Sales Log'!$A$5:$A$1004,">="&B$6,'Sales Log'!$A$5:$A$1004,"<"&DATE(YEAR(B$6),MONTH(B$6)+1,1),'Sales Log'!$B$5:$B$1004,$A13,'Sales Log'!$R$5:$R$1004,"<>EXAMPLE") -> 0 | C13: =SUMIFS('Sales Log'!$G$5:$G$1004,'Sales Log'!$A$5:$A$1004,">="&C$6,'Sales Log'!$A$5:$A$1004,"<"&DATE(YEAR(C$6),MONTH(C$6)+1,1),'Sales Log'!$B$5:$B$1004,$A13,'Sales Log'!$R$5:$R$1004,"<>EXAMPLE") -> 0 | D13: =SUMIFS('Sales Log'!$G$5:$G$1004,'Sales Log'!$A$5:$A$1004,">="&D$6,'Sales Log'!$A$5:$A$1004,"<"&DATE(YEAR(D$6),MONTH(D$6)+1,1),'Sales Log'!$B$5:$B$1004,$A13,'Sales Log'!$R$5:$R$1004,"<>EXAMPLE") -> 0 | E13: =SUMIFS('Sales Log'!$G$5:$G$1004,'Sales Log'!$A$5:$A$1004,">="&E$6,'Sales Log'!$A$5:$A$1004,"<"&DATE(YEAR(E$6),MONTH(E$6)+1,1),'Sales Log'!$B$5:$B$1004,$A13,'Sales Log'!$R$5:$R$1004,"<>EXAMPLE") -> 0 | F13: =SUMIFS('Sales Log'!$G$5:$G$1004,'Sales Log'!$A$5:$A$1004,">="&F$6,'Sales Log'!$A$5:$A$1004,"<"&DATE(YEAR(F$6),MONTH(F$6)+1,1),'Sales Log'!$B$5:$B$1004,$A13,'Sales Log'!$R$5:$R$1004,"<>EXAMPLE") -> 0 | G13: =SUMIFS('Sales Log'!$G$5:$G$1004,'Sales Log'!$A$5:$A$1004,">="&G$6,'Sales Log'!$A$5:$A$1004,"<"&DATE(YEAR(G$6),MONTH(G$6)+1,1),'Sales Log'!$B$5:$B$1004,$A13,'Sales Log'!$R$5:$R$1004,"<>EXAMPLE") -> 0 | H13: =SUMIFS('Sales Log'!$G$5:$G$1004,'Sales Log'!$A$5:$A$1004,">="&H$6,'Sales Log'!$A$5:$A$1004,"<"&DATE(YEAR(H$6),MONTH(H$6)+1,1),'Sales Log'!$B$5:$B$1004,$A13,'Sales Log'!$R$5:$R$1004,"<>EXAMPLE") -> 0 | I13: =SUMIFS('Sales Log'!$G$5:$G$1004,'Sales Log'!$A$5:$A$1004,">="&I$6,'Sales Log'!$A$5:$A$1004,"<"&DATE(YEAR(I$6),MONTH(I$6)+1,1),'Sales Log'!$B$5:$B$1004,$A13,'Sales Log'!$R$5:$R$1004,"<>EXAMPLE") -> 0 | ... M13: =SUMIFS('Sales Log'!$G$5:$G$1004,'Sales Log'!$A$5:$A$1004,">="&M$6,'Sales Log'!$A$5:$A$1004,"<"&DATE(YEAR(M$6),MONTH(M$6)+1,1),'Sales Log'!$B$5:$B$1004,$A13,'Sales Log'!$R$5:$R$1004,"<>EXAMPLE") -> 0 | N13: =SUM(B13:M13) -> 0
A14: ='Chart of Accounts'!$A$73 -> PayPal Business | B14: =SUMIFS('Sales Log'!$G$5:$G$1004,'Sales Log'!$A$5:$A$1004,">="&B$6,'Sales Log'!$A$5:$A$1004,"<"&DATE(YEAR(B$6),MONTH(B$6)+1,1),'Sales Log'!$B$5:$B$1004,$A14,'Sales Log'!$R$5:$R$1004,"<>EXAMPLE") -> 0 | C14: =SUMIFS('Sales Log'!$G$5:$G$1004,'Sales Log'!$A$5:$A$1004,">="&C$6,'Sales Log'!$A$5:$A$1004,"<"&DATE(YEAR(C$6),MONTH(C$6)+1,1),'Sales Log'!$B$5:$B$1004,$A14,'Sales Log'!$R$5:$R$1004,"<>EXAMPLE") -> 0 | D14: =SUMIFS('Sales Log'!$G$5:$G$1004,'Sales Log'!$A$5:$A$1004,">="&D$6,'Sales Log'!$A$5:$A$1004,"<"&DATE(YEAR(D$6),MONTH(D$6)+1,1),'Sales Log'!$B$5:$B$1004,$A14,'Sales Log'!$R$5:$R$1004,"<>EXAMPLE") -> 0 | E14: =SUMIFS('Sales Log'!$G$5:$G$1004,'Sales Log'!$A$5:$A$1004,">="&E$6,'Sales Log'!$A$5:$A$1004,"<"&DATE(YEAR(E$6),MONTH(E$6)+1,1),'Sales Log'!$B$5:$B$1004,$A14,'Sales Log'!$R$5:$R$1004,"<>EXAMPLE") -> 0 | F14: =SUMIFS('Sales Log'!$G$5:$G$1004,'Sales Log'!$A$5:$A$1004,">="&F$6,'Sales Log'!$A$5:$A$1004,"<"&DATE(YEAR(F$6),MONTH(F$6)+1,1),'Sales Log'!$B$5:$B$1004,$A14,'Sales Log'!$R$5:$R$1004,"<>EXAMPLE") -> 0 | G14: =SUMIFS('Sales Log'!$G$5:$G$1004,'Sales Log'!$A$5:$A$1004,">="&G$6,'Sales Log'!$A$5:$A$1004,"<"&DATE(YEAR(G$6),MONTH(G$6)+1,1),'Sales Log'!$B$5:$B$1004,$A14,'Sales Log'!$R$5:$R$1004,"<>EXAMPLE") -> 0 | H14: =SUMIFS('Sales Log'!$G$5:$G$1004,'Sales Log'!$A$5:$A$1004,">="&H$6,'Sales Log'!$A$5:$A$1004,"<"&DATE(YEAR(H$6),MONTH(H$6)+1,1),'Sales Log'!$B$5:$B$1004,$A14,'Sales Log'!$R$5:$R$1004,"<>EXAMPLE") -> 0 | I14: =SUMIFS('Sales Log'!$G$5:$G$1004,'Sales Log'!$A$5:$A$1004,">="&I$6,'Sales Log'!$A$5:$A$1004,"<"&DATE(YEAR(I$6),MONTH(I$6)+1,1),'Sales Log'!$B$5:$B$1004,$A14,'Sales Log'!$R$5:$R$1004,"<>EXAMPLE") -> 0 | ... M14: =SUMIFS('Sales Log'!$G$5:$G$1004,'Sales Log'!$A$5:$A$1004,">="&M$6,'Sales Log'!$A$5:$A$1004,"<"&DATE(YEAR(M$6),MONTH(M$6)+1,1),'Sales Log'!$B$5:$B$1004,$A14,'Sales Log'!$R$5:$R$1004,"<>EXAMPLE") -> 0 | N14: =SUM(B14:M14) -> 0
A15: ='Chart of Accounts'!$A$74 -> Meta shop (FB/IG) | B15: =SUMIFS('Sales Log'!$G$5:$G$1004,'Sales Log'!$A$5:$A$1004,">="&B$6,'Sales Log'!$A$5:$A$1004,"<"&DATE(YEAR(B$6),MONTH(B$6)+1,1),'Sales Log'!$B$5:$B$1004,$A15,'Sales Log'!$R$5:$R$1004,"<>EXAMPLE") -> 0 | C15: =SUMIFS('Sales Log'!$G$5:$G$1004,'Sales Log'!$A$5:$A$1004,">="&C$6,'Sales Log'!$A$5:$A$1004,"<"&DATE(YEAR(C$6),MONTH(C$6)+1,1),'Sales Log'!$B$5:$B$1004,$A15,'Sales Log'!$R$5:$R$1004,"<>EXAMPLE") -> 0 | D15: =SUMIFS('Sales Log'!$G$5:$G$1004,'Sales Log'!$A$5:$A$1004,">="&D$6,'Sales Log'!$A$5:$A$1004,"<"&DATE(YEAR(D$6),MONTH(D$6)+1,1),'Sales Log'!$B$5:$B$1004,$A15,'Sales Log'!$R$5:$R$1004,"<>EXAMPLE") -> 0 | E15: =SUMIFS('Sales Log'!$G$5:$G$1004,'Sales Log'!$A$5:$A$1004,">="&E$6,'Sales Log'!$A$5:$A$1004,"<"&DATE(YEAR(E$6),MONTH(E$6)+1,1),'Sales Log'!$B$5:$B$1004,$A15,'Sales Log'!$R$5:$R$1004,"<>EXAMPLE") -> 0 | F15: =SUMIFS('Sales Log'!$G$5:$G$1004,'Sales Log'!$A$5:$A$1004,">="&F$6,'Sales Log'!$A$5:$A$1004,"<"&DATE(YEAR(F$6),MONTH(F$6)+1,1),'Sales Log'!$B$5:$B$1004,$A15,'Sales Log'!$R$5:$R$1004,"<>EXAMPLE") -> 0 | G15: =SUMIFS('Sales Log'!$G$5:$G$1004,'Sales Log'!$A$5:$A$1004,">="&G$6,'Sales Log'!$A$5:$A$1004,"<"&DATE(YEAR(G$6),MONTH(G$6)+1,1),'Sales Log'!$B$5:$B$1004,$A15,'Sales Log'!$R$5:$R$1004,"<>EXAMPLE") -> 0 | H15: =SUMIFS('Sales Log'!$G$5:$G$1004,'Sales Log'!$A$5:$A$1004,">="&H$6,'Sales Log'!$A$5:$A$1004,"<"&DATE(YEAR(H$6),MONTH(H$6)+1,1),'Sales Log'!$B$5:$B$1004,$A15,'Sales Log'!$R$5:$R$1004,"<>EXAMPLE") -> 0 | I15: =SUMIFS('Sales Log'!$G$5:$G$1004,'Sales Log'!$A$5:$A$1004,">="&I$6,'Sales Log'!$A$5:$A$1004,"<"&DATE(YEAR(I$6),MONTH(I$6)+1,1),'Sales Log'!$B$5:$B$1004,$A15,'Sales Log'!$R$5:$R$1004,"<>EXAMPLE") -> 0 | ... M15: =SUMIFS('Sales Log'!$G$5:$G$1004,'Sales Log'!$A$5:$A$1004,">="&M$6,'Sales Log'!$A$5:$A$1004,"<"&DATE(YEAR(M$6),MONTH(M$6)+1,1),'Sales Log'!$B$5:$B$1004,$A15,'Sales Log'!$R$5:$R$1004,"<>EXAMPLE") -> 0 | N15: =SUM(B15:M15) -> 0
A16: ='Chart of Accounts'!$A$75 -> Faire (wholesale) | B16: =SUMIFS('Sales Log'!$G$5:$G$1004,'Sales Log'!$A$5:$A$1004,">="&B$6,'Sales Log'!$A$5:$A$1004,"<"&DATE(YEAR(B$6),MONTH(B$6)+1,1),'Sales Log'!$B$5:$B$1004,$A16,'Sales Log'!$R$5:$R$1004,"<>EXAMPLE") -> 0 | C16: =SUMIFS('Sales Log'!$G$5:$G$1004,'Sales Log'!$A$5:$A$1004,">="&C$6,'Sales Log'!$A$5:$A$1004,"<"&DATE(YEAR(C$6),MONTH(C$6)+1,1),'Sales Log'!$B$5:$B$1004,$A16,'Sales Log'!$R$5:$R$1004,"<>EXAMPLE") -> 0 | D16: =SUMIFS('Sales Log'!$G$5:$G$1004,'Sales Log'!$A$5:$A$1004,">="&D$6,'Sales Log'!$A$5:$A$1004,"<"&DATE(YEAR(D$6),MONTH(D$6)+1,1),'Sales Log'!$B$5:$B$1004,$A16,'Sales Log'!$R$5:$R$1004,"<>EXAMPLE") -> 0 | E16: =SUMIFS('Sales Log'!$G$5:$G$1004,'Sales Log'!$A$5:$A$1004,">="&E$6,'Sales Log'!$A$5:$A$1004,"<"&DATE(YEAR(E$6),MONTH(E$6)+1,1),'Sales Log'!$B$5:$B$1004,$A16,'Sales Log'!$R$5:$R$1004,"<>EXAMPLE") -> 0 | F16: =SUMIFS('Sales Log'!$G$5:$G$1004,'Sales Log'!$A$5:$A$1004,">="&F$6,'Sales Log'!$A$5:$A$1004,"<"&DATE(YEAR(F$6),MONTH(F$6)+1,1),'Sales Log'!$B$5:$B$1004,$A16,'Sales Log'!$R$5:$R$1004,"<>EXAMPLE") -> 0 | G16: =SUMIFS('Sales Log'!$G$5:$G$1004,'Sales Log'!$A$5:$A$1004,">="&G$6,'Sales Log'!$A$5:$A$1004,"<"&DATE(YEAR(G$6),MONTH(G$6)+1,1),'Sales Log'!$B$5:$B$1004,$A16,'Sales Log'!$R$5:$R$1004,"<>EXAMPLE") -> 0 | H16: =SUMIFS('Sales Log'!$G$5:$G$1004,'Sales Log'!$A$5:$A$1004,">="&H$6,'Sales Log'!$A$5:$A$1004,"<"&DATE(YEAR(H$6),MONTH(H$6)+1,1),'Sales Log'!$B$5:$B$1004,$A16,'Sales Log'!$R$5:$R$1004,"<>EXAMPLE") -> 0 | I16: =SUMIFS('Sales Log'!$G$5:$G$1004,'Sales Log'!$A$5:$A$1004,">="&I$6,'Sales Log'!$A$5:$A$1004,"<"&DATE(YEAR(I$6),MONTH(I$6)+1,1),'Sales Log'!$B$5:$B$1004,$A16,'Sales Log'!$R$5:$R$1004,"<>EXAMPLE") -> 0 | ... M16: =SUMIFS('Sales Log'!$G$5:$G$1004,'Sales Log'!$A$5:$A$1004,">="&M$6,'Sales Log'!$A$5:$A$1004,"<"&DATE(YEAR(M$6),MONTH(M$6)+1,1),'Sales Log'!$B$5:$B$1004,$A16,'Sales Log'!$R$5:$R$1004,"<>EXAMPLE") -> 0 | N16: =SUM(B16:M16) -> 0
A17: ='Chart of Accounts'!$A$76 -> Merchant of record | B17: =SUMIFS('Sales Log'!$G$5:$G$1004,'Sales Log'!$A$5:$A$1004,">="&B$6,'Sales Log'!$A$5:$A$1004,"<"&DATE(YEAR(B$6),MONTH(B$6)+1,1),'Sales Log'!$B$5:$B$1004,$A17,'Sales Log'!$R$5:$R$1004,"<>EXAMPLE") -> 0 | C17: =SUMIFS('Sales Log'!$G$5:$G$1004,'Sales Log'!$A$5:$A$1004,">="&C$6,'Sales Log'!$A$5:$A$1004,"<"&DATE(YEAR(C$6),MONTH(C$6)+1,1),'Sales Log'!$B$5:$B$1004,$A17,'Sales Log'!$R$5:$R$1004,"<>EXAMPLE") -> 0 | D17: =SUMIFS('Sales Log'!$G$5:$G$1004,'Sales Log'!$A$5:$A$1004,">="&D$6,'Sales Log'!$A$5:$A$1004,"<"&DATE(YEAR(D$6),MONTH(D$6)+1,1),'Sales Log'!$B$5:$B$1004,$A17,'Sales Log'!$R$5:$R$1004,"<>EXAMPLE") -> 0 | E17: =SUMIFS('Sales Log'!$G$5:$G$1004,'Sales Log'!$A$5:$A$1004,">="&E$6,'Sales Log'!$A$5:$A$1004,"<"&DATE(YEAR(E$6),MONTH(E$6)+1,1),'Sales Log'!$B$5:$B$1004,$A17,'Sales Log'!$R$5:$R$1004,"<>EXAMPLE") -> 0 | F17: =SUMIFS('Sales Log'!$G$5:$G$1004,'Sales Log'!$A$5:$A$1004,">="&F$6,'Sales Log'!$A$5:$A$1004,"<"&DATE(YEAR(F$6),MONTH(F$6)+1,1),'Sales Log'!$B$5:$B$1004,$A17,'Sales Log'!$R$5:$R$1004,"<>EXAMPLE") -> 0 | G17: =SUMIFS('Sales Log'!$G$5:$G$1004,'Sales Log'!$A$5:$A$1004,">="&G$6,'Sales Log'!$A$5:$A$1004,"<"&DATE(YEAR(G$6),MONTH(G$6)+1,1),'Sales Log'!$B$5:$B$1004,$A17,'Sales Log'!$R$5:$R$1004,"<>EXAMPLE") -> 0 | H17: =SUMIFS('Sales Log'!$G$5:$G$1004,'Sales Log'!$A$5:$A$1004,">="&H$6,'Sales Log'!$A$5:$A$1004,"<"&DATE(YEAR(H$6),MONTH(H$6)+1,1),'Sales Log'!$B$5:$B$1004,$A17,'Sales Log'!$R$5:$R$1004,"<>EXAMPLE") -> 0 | I17: =SUMIFS('Sales Log'!$G$5:$G$1004,'Sales Log'!$A$5:$A$1004,">="&I$6,'Sales Log'!$A$5:$A$1004,"<"&DATE(YEAR(I$6),MONTH(I$6)+1,1),'Sales Log'!$B$5:$B$1004,$A17,'Sales Log'!$R$5:$R$1004,"<>EXAMPLE") -> 0 | ... M17: =SUMIFS('Sales Log'!$G$5:$G$1004,'Sales Log'!$A$5:$A$1004,">="&M$6,'Sales Log'!$A$5:$A$1004,"<"&DATE(YEAR(M$6),MONTH(M$6)+1,1),'Sales Log'!$B$5:$B$1004,$A17,'Sales Log'!$R$5:$R$1004,"<>EXAMPLE") -> 0 | N17: =SUM(B17:M17) -> 0
A18: ='Chart of Accounts'!$A$77 -> Amazon Associates | B18: =SUMIFS('Sales Log'!$G$5:$G$1004,'Sales Log'!$A$5:$A$1004,">="&B$6,'Sales Log'!$A$5:$A$1004,"<"&DATE(YEAR(B$6),MONTH(B$6)+1,1),'Sales Log'!$B$5:$B$1004,$A18,'Sales Log'!$R$5:$R$1004,"<>EXAMPLE") -> 0 | C18: =SUMIFS('Sales Log'!$G$5:$G$1004,'Sales Log'!$A$5:$A$1004,">="&C$6,'Sales Log'!$A$5:$A$1004,"<"&DATE(YEAR(C$6),MONTH(C$6)+1,1),'Sales Log'!$B$5:$B$1004,$A18,'Sales Log'!$R$5:$R$1004,"<>EXAMPLE") -> 0 | D18: =SUMIFS('Sales Log'!$G$5:$G$1004,'Sales Log'!$A$5:$A$1004,">="&D$6,'Sales Log'!$A$5:$A$1004,"<"&DATE(YEAR(D$6),MONTH(D$6)+1,1),'Sales Log'!$B$5:$B$1004,$A18,'Sales Log'!$R$5:$R$1004,"<>EXAMPLE") -> 0 | E18: =SUMIFS('Sales Log'!$G$5:$G$1004,'Sales Log'!$A$5:$A$1004,">="&E$6,'Sales Log'!$A$5:$A$1004,"<"&DATE(YEAR(E$6),MONTH(E$6)+1,1),'Sales Log'!$B$5:$B$1004,$A18,'Sales Log'!$R$5:$R$1004,"<>EXAMPLE") -> 0 | F18: =SUMIFS('Sales Log'!$G$5:$G$1004,'Sales Log'!$A$5:$A$1004,">="&F$6,'Sales Log'!$A$5:$A$1004,"<"&DATE(YEAR(F$6),MONTH(F$6)+1,1),'Sales Log'!$B$5:$B$1004,$A18,'Sales Log'!$R$5:$R$1004,"<>EXAMPLE") -> 0 | G18: =SUMIFS('Sales Log'!$G$5:$G$1004,'Sales Log'!$A$5:$A$1004,">="&G$6,'Sales Log'!$A$5:$A$1004,"<"&DATE(YEAR(G$6),MONTH(G$6)+1,1),'Sales Log'!$B$5:$B$1004,$A18,'Sales Log'!$R$5:$R$1004,"<>EXAMPLE") -> 0 | H18: =SUMIFS('Sales Log'!$G$5:$G$1004,'Sales Log'!$A$5:$A$1004,">="&H$6,'Sales Log'!$A$5:$A$1004,"<"&DATE(YEAR(H$6),MONTH(H$6)+1,1),'Sales Log'!$B$5:$B$1004,$A18,'Sales Log'!$R$5:$R$1004,"<>EXAMPLE") -> 0 | I18: =SUMIFS('Sales Log'!$G$5:$G$1004,'Sales Log'!$A$5:$A$1004,">="&I$6,'Sales Log'!$A$5:$A$1004,"<"&DATE(YEAR(I$6),MONTH(I$6)+1,1),'Sales Log'!$B$5:$B$1004,$A18,'Sales Log'!$R$5:$R$1004,"<>EXAMPLE") -> 0 | ... M18: =SUMIFS('Sales Log'!$G$5:$G$1004,'Sales Log'!$A$5:$A$1004,">="&M$6,'Sales Log'!$A$5:$A$1004,"<"&DATE(YEAR(M$6),MONTH(M$6)+1,1),'Sales Log'!$B$5:$B$1004,$A18,'Sales Log'!$R$5:$R$1004,"<>EXAMPLE") -> 0 | N18: =SUM(B18:M18) -> 0
A19: ='Chart of Accounts'!$A$78 -> Bookshop.org | B19: =SUMIFS('Sales Log'!$G$5:$G$1004,'Sales Log'!$A$5:$A$1004,">="&B$6,'Sales Log'!$A$5:$A$1004,"<"&DATE(YEAR(B$6),MONTH(B$6)+1,1),'Sales Log'!$B$5:$B$1004,$A19,'Sales Log'!$R$5:$R$1004,"<>EXAMPLE") -> 0 | C19: =SUMIFS('Sales Log'!$G$5:$G$1004,'Sales Log'!$A$5:$A$1004,">="&C$6,'Sales Log'!$A$5:$A$1004,"<"&DATE(YEAR(C$6),MONTH(C$6)+1,1),'Sales Log'!$B$5:$B$1004,$A19,'Sales Log'!$R$5:$R$1004,"<>EXAMPLE") -> 0 | D19: =SUMIFS('Sales Log'!$G$5:$G$1004,'Sales Log'!$A$5:$A$1004,">="&D$6,'Sales Log'!$A$5:$A$1004,"<"&DATE(YEAR(D$6),MONTH(D$6)+1,1),'Sales Log'!$B$5:$B$1004,$A19,'Sales Log'!$R$5:$R$1004,"<>EXAMPLE") -> 0 | E19: =SUMIFS('Sales Log'!$G$5:$G$1004,'Sales Log'!$A$5:$A$1004,">="&E$6,'Sales Log'!$A$5:$A$1004,"<"&DATE(YEAR(E$6),MONTH(E$6)+1,1),'Sales Log'!$B$5:$B$1004,$A19,'Sales Log'!$R$5:$R$1004,"<>EXAMPLE") -> 0 | F19: =SUMIFS('Sales Log'!$G$5:$G$1004,'Sales Log'!$A$5:$A$1004,">="&F$6,'Sales Log'!$A$5:$A$1004,"<"&DATE(YEAR(F$6),MONTH(F$6)+1,1),'Sales Log'!$B$5:$B$1004,$A19,'Sales Log'!$R$5:$R$1004,"<>EXAMPLE") -> 0 | G19: =SUMIFS('Sales Log'!$G$5:$G$1004,'Sales Log'!$A$5:$A$1004,">="&G$6,'Sales Log'!$A$5:$A$1004,"<"&DATE(YEAR(G$6),MONTH(G$6)+1,1),'Sales Log'!$B$5:$B$1004,$A19,'Sales Log'!$R$5:$R$1004,"<>EXAMPLE") -> 0 | H19: =SUMIFS('Sales Log'!$G$5:$G$1004,'Sales Log'!$A$5:$A$1004,">="&H$6,'Sales Log'!$A$5:$A$1004,"<"&DATE(YEAR(H$6),MONTH(H$6)+1,1),'Sales Log'!$B$5:$B$1004,$A19,'Sales Log'!$R$5:$R$1004,"<>EXAMPLE") -> 0 | I19: =SUMIFS('Sales Log'!$G$5:$G$1004,'Sales Log'!$A$5:$A$1004,">="&I$6,'Sales Log'!$A$5:$A$1004,"<"&DATE(YEAR(I$6),MONTH(I$6)+1,1),'Sales Log'!$B$5:$B$1004,$A19,'Sales Log'!$R$5:$R$1004,"<>EXAMPLE") -> 0 | ... M19: =SUMIFS('Sales Log'!$G$5:$G$1004,'Sales Log'!$A$5:$A$1004,">="&M$6,'Sales Log'!$A$5:$A$1004,"<"&DATE(YEAR(M$6),MONTH(M$6)+1,1),'Sales Log'!$B$5:$B$1004,$A19,'Sales Log'!$R$5:$R$1004,"<>EXAMPLE") -> 0 | N19: =SUM(B19:M19) -> 0
A20: ='Chart of Accounts'!$A$79 -> Direct (check / ACH / cash) | B20: =SUMIFS('Sales Log'!$G$5:$G$1004,'Sales Log'!$A$5:$A$1004,">="&B$6,'Sales Log'!$A$5:$A$1004,"<"&DATE(YEAR(B$6),MONTH(B$6)+1,1),'Sales Log'!$B$5:$B$1004,$A20,'Sales Log'!$R$5:$R$1004,"<>EXAMPLE") -> 0 | C20: =SUMIFS('Sales Log'!$G$5:$G$1004,'Sales Log'!$A$5:$A$1004,">="&C$6,'Sales Log'!$A$5:$A$1004,"<"&DATE(YEAR(C$6),MONTH(C$6)+1,1),'Sales Log'!$B$5:$B$1004,$A20,'Sales Log'!$R$5:$R$1004,"<>EXAMPLE") -> 0 | D20: =SUMIFS('Sales Log'!$G$5:$G$1004,'Sales Log'!$A$5:$A$1004,">="&D$6,'Sales Log'!$A$5:$A$1004,"<"&DATE(YEAR(D$6),MONTH(D$6)+1,1),'Sales Log'!$B$5:$B$1004,$A20,'Sales Log'!$R$5:$R$1004,"<>EXAMPLE") -> 0 | E20: =SUMIFS('Sales Log'!$G$5:$G$1004,'Sales Log'!$A$5:$A$1004,">="&E$6,'Sales Log'!$A$5:$A$1004,"<"&DATE(YEAR(E$6),MONTH(E$6)+1,1),'Sales Log'!$B$5:$B$1004,$A20,'Sales Log'!$R$5:$R$1004,"<>EXAMPLE") -> 0 | F20: =SUMIFS('Sales Log'!$G$5:$G$1004,'Sales Log'!$A$5:$A$1004,">="&F$6,'Sales Log'!$A$5:$A$1004,"<"&DATE(YEAR(F$6),MONTH(F$6)+1,1),'Sales Log'!$B$5:$B$1004,$A20,'Sales Log'!$R$5:$R$1004,"<>EXAMPLE") -> 0 | G20: =SUMIFS('Sales Log'!$G$5:$G$1004,'Sales Log'!$A$5:$A$1004,">="&G$6,'Sales Log'!$A$5:$A$1004,"<"&DATE(YEAR(G$6),MONTH(G$6)+1,1),'Sales Log'!$B$5:$B$1004,$A20,'Sales Log'!$R$5:$R$1004,"<>EXAMPLE") -> 0 | H20: =SUMIFS('Sales Log'!$G$5:$G$1004,'Sales Log'!$A$5:$A$1004,">="&H$6,'Sales Log'!$A$5:$A$1004,"<"&DATE(YEAR(H$6),MONTH(H$6)+1,1),'Sales Log'!$B$5:$B$1004,$A20,'Sales Log'!$R$5:$R$1004,"<>EXAMPLE") -> 0 | I20: =SUMIFS('Sales Log'!$G$5:$G$1004,'Sales Log'!$A$5:$A$1004,">="&I$6,'Sales Log'!$A$5:$A$1004,"<"&DATE(YEAR(I$6),MONTH(I$6)+1,1),'Sales Log'!$B$5:$B$1004,$A20,'Sales Log'!$R$5:$R$1004,"<>EXAMPLE") -> 0 | ... M20: =SUMIFS('Sales Log'!$G$5:$G$1004,'Sales Log'!$A$5:$A$1004,">="&M$6,'Sales Log'!$A$5:$A$1004,"<"&DATE(YEAR(M$6),MONTH(M$6)+1,1),'Sales Log'!$B$5:$B$1004,$A20,'Sales Log'!$R$5:$R$1004,"<>EXAMPLE") -> 0 | N20: =SUM(B20:M20) -> 0
A21: Total | B21: =SUM(B7:B20) -> 0 | C21: =SUM(C7:C20) -> 0 | D21: =SUM(D7:D20) -> 0 | E21: =SUM(E7:E20) -> 0 | F21: =SUM(F7:F20) -> 0 | G21: =SUM(G7:G20) -> 0 | H21: =SUM(H7:H20) -> 0 | I21: =SUM(I7:I20) -> 0 | ... N21: =SUM(N7:N20) -> 0
A24: Platform fees deducted
A25: Channel | B25: =DATE($B$3,1,1) -> 46023 | C25: =DATE($B$3,2,1) -> 46054 | D25: =DATE($B$3,3,1) -> 46082 | E25: =DATE($B$3,4,1) -> 46113 | F25: =DATE($B$3,5,1) -> 46143 | G25: =DATE($B$3,6,1) -> 46174 | H25: =DATE($B$3,7,1) -> 46204 | I25: =DATE($B$3,8,1) -> 46235 | J25: =DATE($B$3,9,1) -> 46266 | K25: =DATE($B$3,10,1) -> 46296 | L25: =DATE($B$3,11,1) -> 46327 | M25: =DATE($B$3,12,1) -> 46357 | N25: Total
A26: ='Chart of Accounts'!$A$66 -> Amazon KDP | B26: =SUMIFS('Sales Log'!$H$5:$H$1004,'Sales Log'!$A$5:$A$1004,">="&B$25,'Sales Log'!$A$5:$A$1004,"<"&DATE(YEAR(B$25),MONTH(B$25)+1,1),'Sales Log'!$B$5:$B$1004,$A26,'Sales Log'!$R$5:$R$1004,"<>EXAMPLE") -> 0 | C26: =SUMIFS('Sales Log'!$H$5:$H$1004,'Sales Log'!$A$5:$A$1004,">="&C$25,'Sales Log'!$A$5:$A$1004,"<"&DATE(YEAR(C$25),MONTH(C$25)+1,1),'Sales Log'!$B$5:$B$1004,$A26,'Sales Log'!$R$5:$R$1004,"<>EXAMPLE") -> 0 | D26: =SUMIFS('Sales Log'!$H$5:$H$1004,'Sales Log'!$A$5:$A$1004,">="&D$25,'Sales Log'!$A$5:$A$1004,"<"&DATE(YEAR(D$25),MONTH(D$25)+1,1),'Sales Log'!$B$5:$B$1004,$A26,'Sales Log'!$R$5:$R$1004,"<>EXAMPLE") -> 0 | E26: =SUMIFS('Sales Log'!$H$5:$H$1004,'Sales Log'!$A$5:$A$1004,">="&E$25,'Sales Log'!$A$5:$A$1004,"<"&DATE(YEAR(E$25),MONTH(E$25)+1,1),'Sales Log'!$B$5:$B$1004,$A26,'Sales Log'!$R$5:$R$1004,"<>EXAMPLE") -> 0 | F26: =SUMIFS('Sales Log'!$H$5:$H$1004,'Sales Log'!$A$5:$A$1004,">="&F$25,'Sales Log'!$A$5:$A$1004,"<"&DATE(YEAR(F$25),MONTH(F$25)+1,1),'Sales Log'!$B$5:$B$1004,$A26,'Sales Log'!$R$5:$R$1004,"<>EXAMPLE") -> 0 | G26: =SUMIFS('Sales Log'!$H$5:$H$1004,'Sales Log'!$A$5:$A$1004,">="&G$25,'Sales Log'!$A$5:$A$1004,"<"&DATE(YEAR(G$25),MONTH(G$25)+1,1),'Sales Log'!$B$5:$B$1004,$A26,'Sales Log'!$R$5:$R$1004,"<>EXAMPLE") -> 0 | H26: =SUMIFS('Sales Log'!$H$5:$H$1004,'Sales Log'!$A$5:$A$1004,">="&H$25,'Sales Log'!$A$5:$A$1004,"<"&DATE(YEAR(H$25),MONTH(H$25)+1,1),'Sales Log'!$B$5:$B$1004,$A26,'Sales Log'!$R$5:$R$1004,"<>EXAMPLE") -> 0 | I26: =SUMIFS('Sales Log'!$H$5:$H$1004,'Sales Log'!$A$5:$A$1004,">="&I$25,'Sales Log'!$A$5:$A$1004,"<"&DATE(YEAR(I$25),MONTH(I$25)+1,1),'Sales Log'!$B$5:$B$1004,$A26,'Sales Log'!$R$5:$R$1004,"<>EXAMPLE") -> 0 | ... M26: =SUMIFS('Sales Log'!$H$5:$H$1004,'Sales Log'!$A$5:$A$1004,">="&M$25,'Sales Log'!$A$5:$A$1004,"<"&DATE(YEAR(M$25),MONTH(M$25)+1,1),'Sales Log'!$B$5:$B$1004,$A26,'Sales Log'!$R$5:$R$1004,"<>EXAMPLE") -> 0 | N26: =SUM(B26:M26) -> 0
A27: ='Chart of Accounts'!$A$67 -> IngramSpark | B27: =SUMIFS('Sales Log'!$H$5:$H$1004,'Sales Log'!$A$5:$A$1004,">="&B$25,'Sales Log'!$A$5:$A$1004,"<"&DATE(YEAR(B$25),MONTH(B$25)+1,1),'Sales Log'!$B$5:$B$1004,$A27,'Sales Log'!$R$5:$R$1004,"<>EXAMPLE") -> 0 | C27: =SUMIFS('Sales Log'!$H$5:$H$1004,'Sales Log'!$A$5:$A$1004,">="&C$25,'Sales Log'!$A$5:$A$1004,"<"&DATE(YEAR(C$25),MONTH(C$25)+1,1),'Sales Log'!$B$5:$B$1004,$A27,'Sales Log'!$R$5:$R$1004,"<>EXAMPLE") -> 0 | D27: =SUMIFS('Sales Log'!$H$5:$H$1004,'Sales Log'!$A$5:$A$1004,">="&D$25,'Sales Log'!$A$5:$A$1004,"<"&DATE(YEAR(D$25),MONTH(D$25)+1,1),'Sales Log'!$B$5:$B$1004,$A27,'Sales Log'!$R$5:$R$1004,"<>EXAMPLE") -> 0 | E27: =SUMIFS('Sales Log'!$H$5:$H$1004,'Sales Log'!$A$5:$A$1004,">="&E$25,'Sales Log'!$A$5:$A$1004,"<"&DATE(YEAR(E$25),MONTH(E$25)+1,1),'Sales Log'!$B$5:$B$1004,$A27,'Sales Log'!$R$5:$R$1004,"<>EXAMPLE") -> 0 | F27: =SUMIFS('Sales Log'!$H$5:$H$1004,'Sales Log'!$A$5:$A$1004,">="&F$25,'Sales Log'!$A$5:$A$1004,"<"&DATE(YEAR(F$25),MONTH(F$25)+1,1),'Sales Log'!$B$5:$B$1004,$A27,'Sales Log'!$R$5:$R$1004,"<>EXAMPLE") -> 0 | G27: =SUMIFS('Sales Log'!$H$5:$H$1004,'Sales Log'!$A$5:$A$1004,">="&G$25,'Sales Log'!$A$5:$A$1004,"<"&DATE(YEAR(G$25),MONTH(G$25)+1,1),'Sales Log'!$B$5:$B$1004,$A27,'Sales Log'!$R$5:$R$1004,"<>EXAMPLE") -> 0 | H27: =SUMIFS('Sales Log'!$H$5:$H$1004,'Sales Log'!$A$5:$A$1004,">="&H$25,'Sales Log'!$A$5:$A$1004,"<"&DATE(YEAR(H$25),MONTH(H$25)+1,1),'Sales Log'!$B$5:$B$1004,$A27,'Sales Log'!$R$5:$R$1004,"<>EXAMPLE") -> 0 | I27: =SUMIFS('Sales Log'!$H$5:$H$1004,'Sales Log'!$A$5:$A$1004,">="&I$25,'Sales Log'!$A$5:$A$1004,"<"&DATE(YEAR(I$25),MONTH(I$25)+1,1),'Sales Log'!$B$5:$B$1004,$A27,'Sales Log'!$R$5:$R$1004,"<>EXAMPLE") -> 0 | ... M27: =SUMIFS('Sales Log'!$H$5:$H$1004,'Sales Log'!$A$5:$A$1004,">="&M$25,'Sales Log'!$A$5:$A$1004,"<"&DATE(YEAR(M$25),MONTH(M$25)+1,1),'Sales Log'!$B$5:$B$1004,$A27,'Sales Log'!$R$5:$R$1004,"<>EXAMPLE") -> 0 | N27: =SUM(B27:M27) -> 0
